Workbook

Sheet 00_README
A1: NACS 数据收集模板 v1.0
A3: 用途
A4: 本模板用于收集香港 IPO 基石投资量化模型 (NACS) 的回测原始数据。
A5: 覆盖范围: 2022-01-01 至 2026-04-30 期间在 HKEX 主板上市的全部新股 (~250只)。
A7: 工作流
A8: 步骤 1: 在 sheet [01_ipo_master] 用 Wind WSET 函数批量拉出该期间所有 IPO 的代码列表。
A9: 步骤 2: 用 Wind WSS 函数为每只 IPO 拉横截面字段 (发行价/募资额/认购倍数等)。
A10: 步骤 3: 在 sheet [02_ipo_cornerstones] 手填或半自动填写每只IPO的基石明细 (招股书原文+ticket size)。
A11: 步骤 4: 在 sheet [03_company_fundamentals] 填写公司基本面 (招股书披露的3年财务)。
A12: 步骤 5: 在 sheet [04_ccass_unlocks] 填CCASS解禁日前后的持仓变动。
A13: 步骤 6: sheet [05_hsi_macro] 用 Wind WSD 拉恒指日频; sheet [06_price_index] 列出每只IPO要拉的价格区间, 价格数据保存到独立CSV文件。
A14: 步骤 7: 全部填好后, 把整份 xlsx 发给我, 我来跑 loader 灌库 + 回测。
... A56: → 全部就位,可以发我做 loader+回测。

Sheet 01_ipo_master
A1: stock_code | B1: company_name_zh | C1: listing_date | D1: pricing_date | E1: listing_chapter | F1: is_a_h | G1: a_share_code | H1: gics_l2 | I1: offer_price_hkd | J1: offer_price_low | K1: offer_price_high | L1: offering_size_hkd | M1: intl_oversub | N1: public_oversub | O1: clawback_triggered | P1: greenshoe_pct | Q1: sponsor_primary | R1: joint_sponsor_count | S1: sponsor_tier | T1: auditor_tier | U1: pe_at_offer | V1: pe_peer_median | W1: last_round_premium | X1: lockup_months | Y1: is_delisted | Z1: delisting_date | AA1: data_quality_notes | AB1: wind_code_clean | AC1: close_day1_hkd | AD1: open_day1_hkd | AE1: high_day1_hkd | AF1: low_day1_hkd | AG1: listing_board | AH1: h_stock_class | AI1: _orig_chapter | AJ1: is_18a_dual_listing
A2: Wind代码 ★必填 | B2: 证券中文简称 ★必填 | C2: ipo_listdate yyyy-mm-dd ★必填 | D2: ipo_setdate yyyy-mm-dd ★必填 | E2: (枚举) ★必填 | F2: AH双重上市 0/1 ★必填 | G2: 对应A股代码 ○选填 | H2: 行业GICSL2 ★必填 | I2: ipo_price HKD ★必填 | J2: ipo_offerprice_low HKD ○选填 | K2: ipo_offerprice_high HKD ○选填 | L2: ipo_amount HKD ★必填 | M2: ipo_intoversub 倍 ★必填 | N2: ipo_puboversub 倍 ★必填 | O2: (派生) 0/1 ★必填 | P2: ipo_oversinl_pct 比例 ○选填 | Q2: ipo_underwriter ★必填 | R2: (派生:计数+号) 整数 ○选填 | S2: (枚举1/2/3) 1/2/3 ★必填 | T2: (枚举1/2/3) 1/2/3 ○选填 | U2: ipo_pe 倍 ○选填 | V2: (代偿:同GICSL2同PE平均) 倍 ○选填 ⚠偏态分布,极值>100例多为生医医药,谨慎使用 | W2: (招股书:Pre-IPO最后一轮) 比例 ○选填 | X2: 招股书锁定期 月 ○选填 | Y2: 退市状态 0/1 ★必填 | Z2: 退市日期 yyyy-mm-dd ○选填 | AA2: (备注) ○选填 | AB2: Wind代码(去前导0) 仅供公式引用 | AC2: 上市首日收盘价 HKD | AD2: 上市首日开盘价 HKD | AE2: 上市首日最高 HKD | AF2: 上市首日最低 HKD | AG2: 上市板 (主板/创业板) | AH2: H股/红筹股 (首发明细) | AI2: 原E列备份(派生用) | AJ2: 18A 同时为 A+H 双重上市 1=是, 0=否 (派生:ch_18a AND is_a_h=1)
A3: 03296.HK | B3: 华勤技术 | C3: 2026-04-23 | D3: =IFERROR(IF(ISNUMBER($C3),$C3-2,DATEVALUE($C3)-2),"") -> 46133 | E3: a_plus_h | F3: 1 | G3: 603296.SH | H3: TECH_HARDWARE | I3: 77.7 | J3: 70 | K3: 77.7 | L3: 4549000000 | M3: 8 | N3: 531.33 | O3: 0 | P3: 0.15 | Q3: 中金公司+美银证券 | R3: 2 | S3: 1 | T3: 1 | U3: 12.2 | V3: =IFERROR((SUMIFS($U$3:$U$392,$H$3:$H$392,$H3,$U$3:$U$392,">0")-IF(IFERROR($U3,0)>0,$U3,0))/(COUNTIFS($H$3:$H$392,$H3,$U$3:$U$392,">0")-IF(IFERROR($U3,0)>0,1,0)),"") | W3: -0.28 | X3: 6 | Y3: 0 | AA3: ticket_size estimated | AC3: 推荐做法(更稳): | AI3: a_plus_h | AJ3: 0
A4: 3750.HK | B4: 宁德时代 | C4: 45797 | D4: =IFERROR(IF(ISNUMBER($C4),$C4-2,DATEVALUE($C4)-2),"") -> 45795 | E4: a_plus_h | F4: =IF(AND(G4<>"",G4<>0),1,0) -> 1 | G4: 300750.SZ | H4: 工业(HS)-工业工程(HS)-能源储存装置(HS) | I4: 263 | K4: 263 | L4: 41005723900 | M4: 15.17 | N4: 151.15 | O4: =IF(IFERROR(N4*1,0)>=15,1,0) -> 1 | P4: 53.053 | Q4: 法国巴黎证券(亚洲)有限公司,国泰君安证券(香港)有限公司,高盛(亚洲)有限责任公司,摩根士丹利亚洲有限公司,UBS AG Hong Kong Branch,中国国际金融香港证券有限公司,中信建投(国际)融资有限公司,J.P. Morgan Securities (Asia Pacific) Limited,Merrill Lynch (Asia Pacific) Limited | R4: =IF(Q4="",0,LEN(Q4)-LEN(SUBSTITUTE(Q4,",",""))+1) -> 9 | U4: 21.245432 | V4: =IFERROR((SUMIFS($U$3:$U$392,$H$3:$H$392,$H4,$U$3:$U$392,">0")-IF(IFERROR($U4,0)>0,$U4,0))/(COUNTIFS($H$3:$H$392,$H4,$U$3:$U$392,">0")-IF(IFERROR($U4,0)>0,1,0)),"") -> 167.7774 | X4: 6 | Y4: =WSS(AB4,"sec_status") | AB4: =IF(LEFT(A4,1)="0",MID(A4,2,99),A4) -> 3750.HK | AC4: 306.2 | AD4: 296 | AE4: 311.4 | AF4: 291 | AG4: 主板 | AH4: H股 | AI4: 主板 | AJ4: 0
A5: 0300.HK | B5: 美的集团 | C5: 45552 | D5: =IFERROR(IF(ISNUMBER($C5),$C5-2,DATEVALUE($C5)-2),"") -> 45550 | E5: a_plus_h | F5: =IF(AND(G5<>"",G5<>0),1,0) -> 1 | G5: 000333.SZ | H5: 非必需性消费(HS)-家庭电器及用品(HS)-家庭电器(HS) | I5: 54.8 | J5: 52 | K5: 54.8 | L5: 35666497800 | M5: 8.06 | N5: 5.31 | O5: =IF(IFERROR(N5*1,0)>=15,1,0) -> 0 | P5: 46.145 | Q5: 中国国际金融香港证券有限公司,Merrill Lynch (Asia Pacific) Limited,UBS AG Hong Kong Branch,中信里昂证券有限公司,高盛(亚洲)有限责任公司,华泰金融控股(香港)有限公司,广发证券(香港)经纪有限公司,招银国际融资有限公司,法国巴黎证券(亚洲)有限公司,富途证券国际(香港)有限公司 | R5: =IF(Q5="",0,LEN(Q5)-LEN(SUBSTITUTE(Q5,",",""))+1) -> 10 | U5: 11.134372 | V5: =IFERROR((SUMIFS($U$3:$U$392,$H$3:$H$392,$H5,$U$3:$U$392,">0")-IF(IFERROR($U5,0)>0,$U5,0))/(COUNTIFS($H$3:$H$392,$H5,$U$3:$U$392,">0")-IF(IFERROR($U5,0)>0,1,0)),"") -> 6.9752519 | X5: 6 | Y5: =[1]!wss(AB5,"sec_status","cols=1;rows=1") | AB5: =IF(LEFT(A5,1)="0",MID(A5,2,99),A5) -> 300.HK | AC5: 59.1 | AD5: 59.2 | AE5: 60 | AF5: 58 | AG5: 主板 | AH5: H股 | AI5: 主板 | AJ5: 0
A6: 6936.HK | B6: 顺丰控股 | C6: 45623 | D6: =IFERROR(IF(ISNUMBER($C6),$C6-2,DATEVALUE($C6)-2),"") -> 45621 | E6: a_plus_h | F6: =IF(AND(G6<>"",G6<>0),1,0) -> 1 | G6: 002352.SZ | H6: 工业(HS)-工用运输(HS)-航空货运及物流(HS) | I6: 34.3 | J6: 32.3 | K6: 36.3 | L6: 5831000000 | M6: 10.1 | N6: 79.07 | O6: =IF(IFERROR(N6*1,0)>=15,1,0) -> 1 | P6: 0 | Q6: 高盛(亚洲)有限责任公司,华泰金融控股(香港)有限公司,J.P. Morgan Securities (Asia Pacific) Limited,中国国际金融香港证券有限公司,UBS AG Hong Kong Branch,农银国际证券有限公司,中银国际亚洲有限公司,招银国际融资有限公司,星展亚洲融资有限公司,广发证券(香港)经纪有限公司,工银国际证券有限公司 | R6: =IF(Q6="",0,LEN(Q6)-LEN(SUBSTITUTE(Q6,",",""))+1) -> 11 | U6: 18.821727 | V6: =IFERROR((SUMIFS($U$3:$U$392,$H$3:$H$392,$H6,$U$3:$U$392,">0")-IF(IFERROR($U6,0)>0,$U6,0))/(COUNTIFS($H$3:$H$392,$H6,$U$3:$U$392,">0")-IF(IFERROR($U6,0)>0,1,0)),"") -> 16.263307 | X6: 6 | Y6: =[1]!wss(AB6,"sec_status","cols=1;rows=1") -> L | AB6: =IF(LEFT(A6,1)="0",MID(A6,2,99),A6) -> 6936.HK | AC6: 34.3 | AD6: 34.3 | AE6: 35.5 | AF6: 34.3 | AG6: 主板 | AH6: H股 | AI6: 主板 | AJ6: 0
A7: 9973.HK | B7: 奇瑞汽车 | C7: 45925 | D7: =IFERROR(IF(ISNUMBER($C7),$C7-2,DATEVALUE($C7)-2),"") -> 45923 | E7: main_board_profitable | F7: =IF(AND(G7<>"",G7<>0),1,0) -> 0 | H7: 非必需性消费(HS)-汽车(HS)-汽车Ⅲ(HS) | I7: 30.75 | J7: 27.75 | K7: 30.75 | L7: 10417266675 | M7: 11.61 | N7: 308.18 | O7: =IF(IFERROR(N7*1,0)>=15,1,0) -> 1 | P7: 12.493 | Q7: 中国国际金融香港证券有限公司,华泰金融控股(香港)有限公司,广发证券(香港)经纪有限公司,中信里昂证券有限公司,中银国际亚洲有限公司,招银国际融资有限公司,农银国际证券有限公司,富途证券国际(香港)有限公司 | R7: =IF(Q7="",0,LEN(Q7)-LEN(SUBSTITUTE(Q7,",",""))+1) -> 8 | U7: 11.618397 | V7: =IFERROR((SUMIFS($U$3:$U$392,$H$3:$H$392,$H7,$U$3:$U$392,">0")-IF(IFERROR($U7,0)>0,$U7,0))/(COUNTIFS($H$3:$H$392,$H7,$U$3:$U$392,">0")-IF(IFERROR($U7,0)>0,1,0)),"") -> 18.637358 | X7: 6 | Y7: =[1]!wss(AB7,"sec_status","cols=1;rows=1") -> L | AB7: =IF(LEFT(A7,1)="0",MID(A7,2,99),A7) -> 9973.HK | AC7: 31.92 | AD7: 34.2 | AE7: 34.98 | AF7: 31.72 | AG7: 主板 | AH7: H股 | AI7: 主板 | AJ7: 0
A8: 2714.HK | B8: 牧原股份 | C8: 46059 | D8: =IFERROR(IF(ISNUMBER($C8),$C8-2,DATEVALUE($C8)-2),"") -> 46057 | E8: a_plus_h | F8: =IF(AND(G8<>"",G8<>0),1,0) -> 1 | G8: 002714.SZ | H8: 必需性消费(HS)-农业产品(HS)-禽畜肉类(HS) | I8: 39 | K8: 39 | L8: 12098700900 | M8: 8.62 | N8: 5.88 | O8: =IF(IFERROR(N8*1,0)>=15,1,0) -> 0 | P8: 13.95 | Q8: 摩根士丹利亚洲有限公司,中信里昂证券有限公司,高盛(亚洲)有限责任公司,中国国际金融香港证券有限公司,Merrill Lynch (Asia Pacific) Limited,招银国际融资有限公司,招商证券(香港)有限公司,农银国际证券有限公司,中银国际亚洲有限公司,交银国际证券有限公司,建银国际金融有限公司,长江证券经纪(香港)有限公司,中国银河国际证券(香港)有限公司,中国光大证券(香港)有限公司,富途证券国际(香港)有限公司,农银国际融资有限公司 | R8: =IF(Q8="",0,LEN(Q8)-LEN(SUBSTITUTE(Q8,",",""))+1) -> 16 | U8: 11.586709 | V8: =IFERROR((SUMIFS($U$3:$U$392,$H$3:$H$392,$H8,$U$3:$U$392,">0")-IF(IFERROR($U8,0)>0,$U8,0))/(COUNTIFS($H$3:$H$392,$H8,$U$3:$U$392,">0")-IF(IFERROR($U8,0)>0,1,0)),"") -> 12.927582 | X8: 6 | Y8: =[1]!wss(AB8,"sec_status","cols=1;rows=1") -> L | AB8: =IF(LEFT(A8,1)="0",MID(A8,2,99),A8) -> 2714.HK | AC8: 40.52 | AD8: 39 | AE8: 41.72 | AF8: 38.98 | AG8: 主板 | AH8: H股 | AI8: 主板 | AJ8: 0
A9: 3296.HK | B9: 华勤技术 | C9: 46135 | D9: =IFERROR(IF(ISNUMBER($C9),$C9-2,DATEVALUE($C9)-2),"") -> 46133 | E9: a_plus_h | F9: =IF(AND(G9<>"",G9<>0),1,0) -> 1 | G9: 603296.SH | H9: 资讯科技业(HS)-资讯科技器材(HS)-消费性电讯设备(HS) | I9: 77.7 | K9: 77.7 | L9: 4549195140 | M9: 13.34 | N9: 531.33 | O9: =IF(IFERROR(N9*1,0)>=15,1,0) -> 1 | P9: 0 | Q9: 中国国际金融香港证券有限公司,Merrill Lynch (Asia Pacific) Limited,高盛(亚洲)有限责任公司,中信里昂证券有限公司,农银国际证券有限公司,富途证券国际(香港)有限公司,老虎证券(香港)环球有限公司,农银国际融资有限公司 | R9: =IF(Q9="",0,LEN(Q9)-LEN(SUBSTITUTE(Q9,",",""))+1) -> 8 | U9: 18.472672 | V9: =IFERROR((SUMIFS($U$3:$U$392,$H$3:$H$392,$H9,$U$3:$U$392,">0")-IF(IFERROR($U9,0)>0,$U9,0))/(COUNTIFS($H$3:$H$392,$H9,$U$3:$U$392,">0")-IF(IFERROR($U9,0)>0,1,0)),"") -> 44.735767 | X9: 6 | Y9: =[1]!wss(AB9,"sec_status","cols=1;rows=1") -> L | AB9: =IF(LEFT(A9,1)="0",MID(A9,2,99),A9) -> 3296.HK | AC9: 88 | AD9: 87.55 | AE9: 90.95 | AF9: 85 | AG9: 主板 | AH9: H股 | AI9: 主板 | AJ9: 0
A10: 9878.HK | B10: 汇通达网络 | C10: 44610 | D10: =IFERROR(IF(ISNUMBER($C10),$C10-2,DATEVALUE($C10)-2),"") -> 44608 | E10: main_board_profitable | F10: =IF(AND(G10<>"",G10<>0),1,0) -> 0 | H10: 非必需性消费(HS)-专业零售(HS)-线上零售商(HS) | I10: 43 | J10: 43 | K10: 48 | L10: 2318207400 | M10: 2.0497 | N10: 1.67 | O10: =IF(IFERROR(N10*1,0)>=15,1,0) -> 0 | P10: 0.9566 | Q10: 中国国际金融香港证券有限公司,花旗环球金融亚洲有限公司,Citigroup Global Markets Limited,华兴证券(香港)有限公司,香港上海汇丰银行有限公司,海通国际证券有限公司,浦银国际融资有限公司,招银国际融资有限公司,交银国际证券有限公司,中银国际亚洲有限公司,建银国际金融有限公司,农银国际证券有限公司,富途证券国际(香港)有限公司,联合证券有限公司 | R10: =IF(Q10="",0,LEN(Q10)-LEN(SUBSTITUTE(Q10,",",""))+1) -> 14 | U10: -50.029372 | V10: =IFERROR((SUMIFS($U$3:$U$392,$H$3:$H$392,$H10,$U$3:$U$392,">0")-IF(IFERROR($U10,0)>0,$U10,0))/(COUNTIFS($H$3:$H$392,$H10,$U$3:$U$392,">0")-IF(IFERROR($U10,0)>0,1,0)),"") -> 28.634596 | X10: 6 | Y10: =[1]!wss(AB10,"sec_status","cols=1;rows=1") -> L | AB10: =IF(LEFT(A10,1)="0",MID(A10,2,99),A10) -> 9878.HK | AC10: 45.1 | AD10: 43.55 | AE10: 45.5 | AF10: 43 | AG10: 主板 | AH10: H股 | AI10: 主板 | AJ10: 0
A11: 6963.HK | B11: 阳光保险 | C11: 44904 | D11: =IFERROR(IF(ISNUMBER($C11),$C11-2,DATEVALUE($C11)-2),"") -> 44902 | E11: main_board_profitable | F11: =IF(AND(G11<>"",G11<>0),1,0) -> 0 | H11: 金融业(HS)-保险(HS)-保险Ⅲ(HS) | I11: 5.83 | J11: 5.83 | K11: 6.45 | L11: 6705389075 | M11: 1.34 | N11: 0.13 | O11: =IF(IFERROR(N11*1,0)>=15,1,0) -> 0 | P11: 0 | Q11: 华泰金融控股(香港)有限公司,中国国际金融香港证券有限公司,UBS AG Hong Kong Branch,建银国际金融有限公司,法国巴黎证券(亚洲)有限公司,交银国际证券有限公司,工银国际证券有限公司,招银国际融资有限公司,中信里昂证券有限公司,农银国际证券有限公司,招商证券(香港)有限公司,申万宏源证券(香港)有限公司,东吴证券国际经纪有限公司 | R11: =IF(Q11="",0,LEN(Q11)-LEN(SUBSTITUTE(Q11,",",""))+1) -> 13 | U11: 9.3189273 | V11: =IFERROR((SUMIFS($U$3:$U$392,$H$3:$H$392,$H11,$U$3:$U$392,">0")-IF(IFERROR($U11,0)>0,$U11,0))/(COUNTIFS($H$3:$H$392,$H11,$U$3:$U$392,">0")-IF(IFERROR($U11,0)>0,1,0)),"") -> 140.71723 | Y11: =[1]!wss(AB11,"sec_status","cols=1;rows=1") -> L | AB11: =IF(LEFT(A11,1)="0",MID(A11,2,99),A11) -> 6963.HK | AC11: 5.83 | AD11: 5.83 | AE11: 5.83 | AF11: 5.51 | AG11: 主板 | AH11: H股 | AI11: 主板 | AJ11: 0
A12: 2423.HK | B12: 贝壳-W | C12: 44692 | D12: =IFERROR(IF(ISNUMBER($C12),$C12-2,DATEVALUE($C12)-2),"") -> 44690 | E12: 18a | F12: =IF(AND(G12<>"",G12<>0),1,0) -> 0 | H12: 地产建筑业(HS)-地产(HS)-地产代理(HS) | L12: 0 | M12: 0 | N12: 0 | O12: =IF(IFERROR(N12*1,0)>=15,1,0) -> 0 | P12: 0 | Q12: 0 | R12: =IF(Q12="",0,LEN(Q12)-LEN(SUBSTITUTE(Q12,",",""))+1) -> 1 | U12: 0 | V12: =IFERROR((SUMIFS($U$3:$U$392,$H$3:$H$392,$H12,$U$3:$U$392,">0")-IF(IFERROR($U12,0)>0,$U12,0))/(COUNTIFS($H$3:$H$392,$H12,$U$3:$U$392,">0")-IF(IFERROR($U12,0)>0,1,0)),"") | Y12: =[1]!wss(AB12,"sec_status","cols=1;rows=1") -> L | AB12: =IF(LEFT(A12,1)="0",MID(A12,2,99),A12) -> 2423.HK | AC12: 30.75 | AD12: 30 | AE12: 32.45 | AF12: 30 | AG12: 主板 | AI12: 主板 | AJ12: 0
A13: 6031.HK | B13: 三一重工 | C13: 45958 | D13: =IFERROR(IF(ISNUMBER($C13),$C13-2,DATEVALUE($C13)-2),"") -> 45956 | E13: a_plus_h | F13: =IF(AND(G13<>"",G13<>0),1,0) -> 1 | G13: 600031.SH | H13: 工业(HS)-工业工程(HS)-重型机械(HS) | I13: 21.3 | J13: 20.3 | K13: 21.3 | L13: 15349086720 | M13: 13.96 | N13: 52.93 | O13: =IF(IFERROR(N13*1,0)>=15,1,0) -> 1 | P13: 18.824 | Q13: 中信里昂证券有限公司,中国国际金融香港证券有限公司,中银国际亚洲有限公司,招商证券(香港)有限公司,农银国际证券有限公司,工银国际证券有限公司,农银国际融资有限公司 | R13: =IF(Q13="",0,LEN(Q13)-LEN(SUBSTITUTE(Q13,",",""))+1) -> 7 | U13: 30.058394 | V13: =IFERROR((SUMIFS($U$3:$U$392,$H$3:$H$392,$H13,$U$3:$U$392,">0")-IF(IFERROR($U13,0)>0,$U13,0))/(COUNTIFS($H$3:$H$392,$H13,$U$3:$U$392,">0")-IF(IFERROR($U13,0)>0,1,0)),"") -> 19.366735 | X13: 6 | Y13: =[1]!wss(AB13,"sec_status","cols=1;rows=1") -> L | AB13: =IF(LEFT(A13,1)="0",MID(A13,2,99),A13) -> 6031.HK | AC13: 21.9 | AD13: 21.3 | AE13: 22.3 | AF13: 21.3 | AG13: 主板 | AH13: H股 | AI13: 主板 | AJ13: 0
A14: 1880.HK | B14: 中国中免 | C14: 44798 | D14: =IFERROR(IF(ISNUMBER($C14),$C14-2,DATEVALUE($C14)-2),"") -> 44796 | E14: a_plus_h | F14: =IF(AND(G14<>"",G14<>0),1,0) -> 1 | G14: 601888.SH | H14: 非必需性消费(HS)-旅游及消闲设施(HS)-旅游及观光(HS) | I14: 158 | J14: 143.5 | K14: 165.5 | L14: 18388593000 | M14: 4.7 | N14: 1.06 | O14: =IF(IFERROR(N14*1,0)>=15,1,0) -> 0 | P14: 21.198 | Q14: 中国国际金融香港证券有限公司,UBS AG Hong Kong Branch,建银国际金融有限公司,中信里昂证券有限公司,海通国际证券有限公司,农银国际证券有限公司,中银国际亚洲有限公司,交银国际证券有限公司,招银国际融资有限公司,中信建投(国际)融资有限公司,星展亚洲融资有限公司,国泰君安证券(香港)有限公司,工银国际证券有限公司,中国银河国际证券(香港)有限公司,东吴证券国际经纪有限公司 | R14: =IF(Q14="",0,LEN(Q14)-LEN(SUBSTITUTE(Q14,",",""))+1) -> 15 | U14: 27.296115 | V14: =IFERROR((SUMIFS($U$3:$U$392,$H$3:$H$392,$H14,$U$3:$U$392,">0")-IF(IFERROR($U14,0)>0,$U14,0))/(COUNTIFS($H$3:$H$392,$H14,$U$3:$U$392,">0")-IF(IFERROR($U14,0)>0,1,0)),"") | X14: 6 | Y14: =[1]!wss(AB14,"sec_status","cols=1;rows=1") -> L | AB14: =IF(LEFT(A14,1)="0",MID(A14,2,99),A14) -> 1880.HK | AC14: 158 | AD14: 120 | AE14: 159.3 | AF14: 120 | AG14: 主板 | AH14: H股 | AI14: 主板 | AJ14: 0
A15: 1519.HK | B15: 极兔速递-W | C15: 45226 | D15: =IFERROR(IF(ISNUMBER($C15),$C15-2,DATEVALUE($C15)-2),"") -> 45224 | E15: 18a | F15: =IF(AND(G15<>"",G15<>0),1,0) -> 0 | H15: 工业(HS)-工用运输(HS)-航空货运及物流(HS) | I15: 12 | J15: 12 | K15: 12 | L15: 3918604800 | M15: 1.91 | N15: 1.36 | O15: =IF(IFERROR(N15*1,0)>=15,1,0) -> 0 | P15: 0 | Q15: 国泰君安证券(香港)有限公司,星展亚洲融资有限公司,中国银河国际证券(香港)有限公司,富途证券国际(香港)有限公司,老虎证券(香港)环球有限公司,华盛资本证券有限公司,富明证券有限公司,复星国际证券有限公司,摩根士丹利亚洲有限公司,Merrill Lynch (Asia Pacific) Limited,中国国际金融香港证券有限公司,UBS AG Hong Kong Branch,建银国际金融有限公司,招银国际融资有限公司,华泰金融控股(香港)有限公司,中银国际亚洲有限公司,农银国际证券有限公司,交银国际证券有限公司,工银国际证券有限公司,德意志银行香港分行,大和资本市场香港有限公司 | R15: =IF(Q15="",0,LEN(Q15)-LEN(SUBSTITUTE(Q15,",",""))+1) -> 21 | U15: 8.1892873 | V15: =IFERROR((SUMIFS($U$3:$U$392,$H$3:$H$392,$H15,$U$3:$U$392,">0")-IF(IFERROR($U15,0)>0,$U15,0))/(COUNTIFS($H$3:$H$392,$H15,$U$3:$U$392,">0")-IF(IFERROR($U15,0)>0,1,0)),"") -> 21.579526 | X15: 6 | Y15: =[1]!wss(AB15,"sec_status","cols=1;rows=1") -> L | AB15: =IF(LEFT(A15,1)="0",MID(A15,2,99),A15) -> 1519.HK | AC15: 12 | AD15: 12 | AE15: 12.2 | AF15: 11.8 | AG15: 主板 | AI15: 主板 | AJ15: 0
A16: 0699.HK | B16: 均胜电子 | C16: 45967 | D16: =IFERROR(IF(ISNUMBER($C16),$C16-2,DATEVALUE($C16)-2),"") -> 45965 | E16: a_plus_h | F16: =IF(AND(G16<>"",G16<>0),1,0) -> 1 | G16: 600699.SH | H16: 非必需性消费(HS)-汽车(HS)-汽车零件(HS) | I16: 22 | K16: 23.6 | L16: 3412200000 | M16: 9.78 | N16: 147.67 | O16: =IF(IFERROR(N16*1,0)>=15,1,0) -> 1 | P16: 0 | Q16: 中国国际金融香港证券有限公司,UBS AG Hong Kong Branch,广发证券(香港)经纪有限公司,农银国际证券有限公司,华兴证券(香港)有限公司,招银国际融资有限公司,UBS Securities Hong Kong Limited,农银国际融资有限公司 | R16: =IF(Q16="",0,LEN(Q16)-LEN(SUBSTITUTE(Q16,",",""))+1) -> 8 | U16: 32.893961 | V16: =IFERROR((SUMIFS($U$3:$U$392,$H$3:$H$392,$H16,$U$3:$U$392,">0")-IF(IFERROR($U16,0)>0,$U16,0))/(COUNTIFS($H$3:$H$392,$H16,$U$3:$U$392,">0")-IF(IFERROR($U16,0)>0,1,0)),"") -> 10.854154 | X16: 6 | Y16: =[1]!wss(AB16,"sec_status","cols=1;rows=1") | AB16: =IF(LEFT(A16,1)="0",MID(A16,2,99),A16) -> 699.HK | AC16: 20.24 | AD16: 21.5 | AE16: 21.5 | AF16: 19.85 | AG16: 主板 | AH16: H股 | AI16: 主板 | AJ16: 0
A17: 9866.HK | B17: 蔚来-SW | C17: 44630 | D17: =IFERROR(IF(ISNUMBER($C17),$C17-2,DATEVALUE($C17)-2),"") -> 44628 | E17: secondary | F17: =IF(AND(G17<>"",G17<>0),1,0) -> 0 | H17: 非必需性消费(HS)-汽车(HS)-汽车Ⅲ(HS) | L17: 0 | M17: 0 | N17: 0 | O17: =IF(IFERROR(N17*1,0)>=15,1,0) -> 0 | P17: 0 | Q17: 0 | R17: =IF(Q17="",0,LEN(Q17)-LEN(SUBSTITUTE(Q17,",",""))+1) -> 1 | U17: 0 | V17: =IFERROR((SUMIFS($U$3:$U$392,$H$3:$H$392,$H17,$U$3:$U$392,">0")-IF(IFERROR($U17,0)>0,$U17,0))/(COUNTIFS($H$3:$H$392,$H17,$U$3:$U$392,">0")-IF(IFERROR($U17,0)>0,1,0)),"") -> 16.882618 | Y17: =[1]!wss(AB17,"sec_status","cols=1;rows=1") -> L | AB17: =IF(LEFT(A17,1)="0",MID(A17,2,99),A17) -> 9866.HK | AC17: 158.9 | AD17: 160 | AE17: 169.5 | AF17: 158.8 | AG17: 主板 | AI17: 主板 | AJ17: 0
A18: 6613.HK | B18: 蓝思科技 | C18: 45847 | D18: =IFERROR(IF(ISNUMBER($C18),$C18-2,DATEVALUE($C18)-2),"") -> 45845 | E18: a_plus_h | F18: =IF(AND(G18<>"",G18<>0),1,0) -> 1 | G18: 300433.SZ | H18: 工业(HS)-工业工程(HS)-电子零件(HS) | I18: 18.18 | J18: 17.38 | K18: 18.18 | L18: 5483000736 | M18: 16.68 | N18: 462.76 | O18: =IF(IFERROR(N18*1,0)>=15,1,0) -> 1 | P18: 7.108 | Q18: 中信里昂证券有限公司,Merrill Lynch (Asia Pacific) Limited,农银国际证券有限公司,中银国际亚洲有限公司,富途证券国际(香港)有限公司,中航资信环球资产管理有限公司,农银国际融资有限公司 | R18: =IF(Q18="",0,LEN(Q18)-LEN(SUBSTITUTE(Q18,",",""))+1) -> 7 | U18: 24.366614 | V18: =IFERROR((SUMIFS($U$3:$U$392,$H$3:$H$392,$H18,$U$3:$U$392,">0")-IF(IFERROR($U18,0)>0,$U18,0))/(COUNTIFS($H$3:$H$392,$H18,$U$3:$U$392,">0")-IF(IFERROR($U18,0)>0,1,0)),"") -> 35.876825 | X18: 6 | Y18: =[1]!wss(AB18,"sec_status","cols=1;rows=1") -> L | AB18: =IF(LEFT(A18,1)="0",MID(A18,2,99),A18) -> 6613.HK | AC18: 19.84 | AD18: 18.88 | AE18: 19.98 | AF18: 18.54 | AG18: 主板 | AH18: H股 | AI18: 主板 | AJ18: 0
A19: 9696.HK | B19: 天齐锂业 | C19: 44755 | D19: =IFERROR(IF(ISNUMBER($C19),$C19-2,DATEVALUE($C19)-2),"") -> 44753 | E19: a_plus_h | F19: =IF(AND(G19<>"",G19<>0),1,0) -> 1 | G19: 002466.SZ | H19: 原材料业(HS)-一般金属及矿石(HS)-其他金属及矿物(HS) | I19: 82 | J19: 69 | K19: 82 | L19: 13458020400 | M19: 5.2 | N19: 9.3 | O19: =IF(IFERROR(N19*1,0)>=15,1,0) -> 0 | P19: 0 | Q19: 摩根士丹利亚洲有限公司,中国国际金融香港证券有限公司,招银国际融资有限公司,法国巴黎证券(亚洲)有限公司,瑞士信贷(香港)有限公司,Banco BTG Pactual S.A.-Cayman Branch,中国银河国际证券(香港)有限公司,富途证券国际(香港)有限公司,华泰金融控股(香港)有限公司 | R19: =IF(Q19="",0,LEN(Q19)-LEN(SUBSTITUTE(Q19,",",""))+1) -> 9 | U19: 30.152691 | V19: =IFERROR((SUMIFS($U$3:$U$392,$H$3:$H$392,$H19,$U$3:$U$392,">0")-IF(IFERROR($U19,0)>0,$U19,0))/(COUNTIFS($H$3:$H$392,$H19,$U$3:$U$392,">0")-IF(IFERROR($U19,0)>0,1,0)),"") -> 34.494409 | X19: 6 | Y19: =[1]!wss(AB19,"sec_status","cols=1;rows=1") -> L | AB19: =IF(LEFT(A19,1)="0",MID(A19,2,99),A19) -> 9696.HK | AC19: 82 | AD19: 74.5 | AE19: 82 | AF19: 72.65 | AG19: 主板 | AH19: H股 | AI19: 主板 | AJ19: 0
A20: 9927.HK | B20: 赛力斯 | C20: 45966 | D20: =IFERROR(IF(ISNUMBER($C20),$C20-2,DATEVALUE($C20)-2),"") -> 45964 | E20: a_plus_h | F20: =IF(AND(G20<>"",G20<>0),1,0) -> 1 | G20: 601127.SH | H20: 非必需性消费(HS)-汽车(HS)-汽车Ⅲ(HS) | I20: 131.5 | K20: 131.5 | L20: 14283398500 | M20: 8.61 | N20: 132.68 | O20: =IF(IFERROR(N20*1,0)>=15,1,0) -> 1 | P20: 0 | Q20: 中国国际金融香港证券有限公司,中国银河国际证券(香港)有限公司,华泰金融控股(香港)有限公司 | R20: =IF(Q20="",0,LEN(Q20)-LEN(SUBSTITUTE(Q20,",",""))+1) -> 3 | U20: 35.676237 | V20: =IFERROR((SUMIFS($U$3:$U$392,$H$3:$H$392,$H20,$U$3:$U$392,">0")-IF(IFERROR($U20,0)>0,$U20,0))/(COUNTIFS($H$3:$H$392,$H20,$U$3:$U$392,">0")-IF(IFERROR($U20,0)>0,1,0)),"") -> 10.618078 | X20: 6 | Y20: =[1]!wss(AB20,"sec_status","cols=1;rows=1") -> L | AB20: =IF(LEFT(A20,1)="0",MID(A20,2,99),A20) -> 9927.HK | AC20: 131.5 | AD20: 128.9 | AE20: 131.5 | AF20: 118 | AG20: 主板 | AH20: H股 | AI20: 主板 | AJ20: 0
A21: 2579.HK | B21: 中伟新材 | C21: 45978 | D21: =IFERROR(IF(ISNUMBER($C21),$C21-2,DATEVALUE($C21)-2),"") -> 45976 | E21: a_plus_h | F21: =IF(AND(G21<>"",G21<>0),1,0) -> 1 | G21: 300919.SZ | H21: 原材料业(HS)-原材料(HS)-特殊化工用品(HS) | I21: 34 | J21: 34 | K21: 37.8 | L21: 3543663600 | M21: 4.08 | N21: 27.9 | O21: =IF(IFERROR(N21*1,0)>=15,1,0) -> 1 | P21: 0 | Q21: 摩根士丹利亚洲有限公司,华泰金融控股(香港)有限公司,中国国际金融香港证券有限公司,法国巴黎证券(亚洲)有限公司,农银国际融资有限公司,农银国际证券有限公司,中银国际亚洲有限公司,工银国际证券有限公司,建银国际金融有限公司,瑞穗证券亚洲有限公司,老虎证券(香港)环球有限公司,第一上海证券有限公司 | R21: =IF(Q21="",0,LEN(Q21)-LEN(SUBSTITUTE(Q21,",",""))+1) -> 12 | U21: 22.365868 | V21: =IFERROR((SUMIFS($U$3:$U$392,$H$3:$H$392,$H21,$U$3:$U$392,">0")-IF(IFERROR($U21,0)>0,$U21,0))/(COUNTIFS($H$3:$H$392,$H21,$U$3:$U$392,">0")-IF(IFERROR($U21,0)>0,1,0)),"") -> 10.481443 | X21: 6 | Y21: =[1]!wss(AB21,"sec_status","cols=1;rows=1") -> L | AB21: =IF(LEFT(A21,1)="0",MID(A21,2,99),A21) -> 2579.HK | AC21: 33.96 | AD21: 34 | AE21: 34 | AF21: 32 | AG21: 主板 | AH21: H股 | AI21: 主板 | AJ21: 0
A22: 6655.HK | B22: 华新建材 | C22: 44648 | D22: =IFERROR(IF(ISNUMBER($C22),$C22-2,DATEVALUE($C22)-2),"") -> 44646 | E22: a_plus_h | F22: =IF(AND(G22<>"",G22<>0),1,0) -> 1 | G22: 600801.SH | H22: 地产建筑业(HS)-建筑(HS)-建筑材料(HS) | L22: 0 | M22: 0 | N22: 0 | O22: =IF(IFERROR(N22*1,0)>=15,1,0) -> 0 | P22: 0 | Q22: 0 | R22: =IF(Q22="",0,LEN(Q22)-LEN(SUBSTITUTE(Q22,",",""))+1) -> 1 | U22: 0 | V22: =IFERROR((SUMIFS($U$3:$U$392,$H$3:$H$392,$H22,$U$3:$U$392,">0")-IF(IFERROR($U22,0)>0,$U22,0))/(COUNTIFS($H$3:$H$392,$H22,$U$3:$U$392,">0")-IF(IFERROR($U22,0)>0,1,0)),"") -> 10.989343 | Y22: =[1]!wss(AB22,"sec_status","cols=1;rows=1") -> L | AB22: =IF(LEFT(A22,1)="0",MID(A22,2,99),A22) -> 6655.HK | AC22: 13.8 | AD22: 14.74 | AE22: 14.74 | AF22: 11.2 | AG22: 主板 | AH22: H股 | AI22: 主板 | AJ22: 0
A23: 2602.HK | B23: 万物云 | C23: 44833 | D23: =IFERROR(IF(ISNUMBER($C23),$C23-2,DATEVALUE($C23)-2),"") -> 44831 | E23: main_board_profitable | F23: =IF(AND(G23<>"",G23<>0),1,0) -> 0 | H23: 地产建筑业(HS)-地产(HS)-物业服务及管理(HS) | I23: 49.35 | J23: 47.1 | K23: 52.7 | L23: 6319203345 | M23: 3.3 | N23: 0.82 | O23: =IF(IFERROR(N23*1,0)>=15,1,0) -> 0 | P23: 5.551 | Q23: 高盛(亚洲)有限责任公司,招银国际融资有限公司,中银国际亚洲有限公司,建银国际金融有限公司,国信证券(香港)融资有限公司,工银国际证券有限公司,农银国际证券有限公司,中信里昂证券有限公司,花旗环球金融亚洲有限公司,Citigroup Global Markets Limited,工银国际融资有限公司 | R23: =IF(Q23="",0,LEN(Q23)-LEN(SUBSTITUTE(Q23,",",""))+1) -> 11 | U23: 28.23878 | V23: =IFERROR((SUMIFS($U$3:$U$392,$H$3:$H$392,$H23,$U$3:$U$392,">0")-IF(IFERROR($U23,0)>0,$U23,0))/(COUNTIFS($H$3:$H$392,$H23,$U$3:$U$392,">0")-IF(IFERROR($U23,0)>0,1,0)),"") -> 18.089727 | X23: 6 | Y23: =[1]!wss(AB23,"sec_status","cols=1;rows=1") -> L | AB23: =IF(LEFT(A23,1)="0",MID(A23,2,99),A23) -> 2602.HK | AC23: 46 | AD23: 45.6 | AE23: 47.45 | AF23: 42.05 | AG23: 主板 | AH23: H股 | AI23: 主板 | AJ23: 0
A24: 1698.HK | B24: 腾讯音乐-SW | C24: 44825 | D24: =IFERROR(IF(ISNUMBER($C24),$C24-2,DATEVALUE($C24)-2),"") -> 44823 | E24: secondary | F24: =IF(AND(G24<>"",G24<>0),1,0) -> 0 | H24: 非必需性消费(HS)-媒体及娱乐(HS)-影视娱乐(HS) | L24: 0 | M24: 0 | N24: 0 | O24: =IF(IFERROR(N24*1,0)>=15,1,0) -> 0 | P24: 0 | Q24: 0 | R24: =IF(Q24="",0,LEN(Q24)-LEN(SUBSTITUTE(Q24,",",""))+1) -> 1 | U24: 0 | V24: =IFERROR((SUMIFS($U$3:$U$392,$H$3:$H$392,$H24,$U$3:$U$392,">0")-IF(IFERROR($U24,0)>0,$U24,0))/(COUNTIFS($H$3:$H$392,$H24,$U$3:$U$392,">0")-IF(IFERROR($U24,0)>0,1,0)),"") -> 71.440653 | Y24: =[1]!wss(AB24,"sec_status","cols=1;rows=1") -> L | AB24: =IF(LEFT(A24,1)="0",MID(A24,2,99),A24) -> 1698.HK | AC24: 18.22 | AD24: 18 | AE24: 18.3 | AF24: 18 | AG24: 主板 | AI24: 主板 | AJ24: 0
A25: 9611.HK | B25: 龙旗科技 | C25: 46044 | D25: =IFERROR(IF(ISNUMBER($C25),$C25-2,DATEVALUE($C25)-2),"") -> 46042 | E25: a_plus_h | F25: =IF(AND(G25<>"",G25<>0),1,0) -> 1 | G25: 603341.SH | H25: 资讯科技业(HS)-资讯科技器材(HS)-消费性电讯设备(HS) | I25: 31 | K25: 31 | L25: 1620032100 | M25: 9.02 | N25: 1149.76 | O25: =IF(IFERROR(N25*1,0)>=15,1,0) -> 1 | P25: 0 | Q25: 花旗环球金融亚洲有限公司,Citigroup Global Markets Limited,海通国际证券有限公司,国泰君安证券(香港)有限公司,华泰金融控股(香港)有限公司,农银国际证券有限公司,富途证券国际(香港)有限公司,老虎证券(香港)环球有限公司,农银国际融资有限公司 | R25: =IF(Q25="",0,LEN(Q25)-LEN(SUBSTITUTE(Q25,",",""))+1) -> 9 | U25: 29.936494 | V25: =IFERROR((SUMIFS($U$3:$U$392,$H$3:$H$392,$H25,$U$3:$U$392,">0")-IF(IFERROR($U25,0)>0,$U25,0))/(COUNTIFS($H$3:$H$392,$H25,$U$3:$U$392,">0")-IF(IFERROR($U25,0)>0,1,0)),"") -> 39.003856 | X25: 6 | Y25: =[1]!wss(AB25,"sec_status","cols=1;rows=1") -> L | AB25: =IF(LEFT(A25,1)="0",MID(A25,2,99),A25) -> 9611.HK | AC25: 32.1 | AD25: 35 | AE25: 36.86 | AF25: 31.22 | AG25: 主板 | AH25: H股 | AI25: 主板 | AJ25: 0
A26: 3931.HK | B26: 中创新航 | C26: 44840 | D26: =IFERROR(IF(ISNUMBER($C26),$C26-2,DATEVALUE($C26)-2),"") -> 44838 | E26: main_board_profitable | F26: =IF(AND(G26<>"",G26<>0),1,0) -> 0 | H26: 工业(HS)-工业工程(HS)-能源储存装置(HS) | I26: 38 | J26: 38 | K26: 51 | L26: 10102121400 | M26: 2.11 | N26: 0.21 | O26: =IF(IFERROR(N26*1,0)>=15,1,0) -> 0 | P26: 0 | Q26: 华泰金融控股(香港)有限公司,J.P. Morgan Securities (Asia Pacific) Limited,J.P. Morgan Securities plc,花旗环球金融亚洲有限公司,Citigroup Global Markets Limited,瑞士信贷(香港)有限公司 | R26: =IF(Q26="",0,LEN(Q26)-LEN(SUBSTITUTE(Q26,",",""))+1) -> 6 | U26: 393.22777 | V26: =IFERROR((SUMIFS($U$3:$U$392,$H$3:$H$392,$H26,$U$3:$U$392,">0")-IF(IFERROR($U26,0)>0,$U26,0))/(COUNTIFS($H$3:$H$392,$H26,$U$3:$U$392,">0")-IF(IFERROR($U26,0)>0,1,0)),"") -> 93.380932 | X26: 6 | Y26: =[1]!wss(AB26,"sec_status","cols=1;rows=1") -> L | AB26: =IF(LEFT(A26,1)="0",MID(A26,2,99),A26) -> 3931.HK | AC26: 38 | AD26: 38 | AE26: 38.45 | AF26: 37.15 | AG26: 主板 | AH26: H股 | AI26: 主板 | AJ26: 0
A27: 2580.HK | B27: 奥克斯电气 | C27: 45902 | D27: =IFERROR(IF(ISNUMBER($C27),$C27-2,DATEVALUE($C27)-2),"") -> 45900 | E27: main_board_profitable | F27: =IF(AND(G27<>"",G27<>0),1,0) -> 0 | H27: 非必需性消费(HS)-家庭电器及用品(HS)-家庭电器(HS) | I27: 17.42 | J27: 16 | K27: 17.42 | L27: 4150057184 | M27: 8.3 | N27: 557.2 | O27: =IF(IFERROR(N27*1,0)>=15,1,0) -> 1 | P27: 0 | Q27: 中国国际金融香港证券有限公司,东方证券(香港)有限公司,农银国际证券有限公司,工银国际证券有限公司,富途证券国际(香港)有限公司,农银国际融资有限公司 | R27: =IF(Q27="",0,LEN(Q27)-LEN(SUBSTITUTE(Q27,",",""))+1) -> 6 | U27: 8.8038818 | V27: =IFERROR((SUMIFS($U$3:$U$392,$H$3:$H$392,$H27,$U$3:$U$392,">0")-IF(IFERROR($U27,0)>0,$U27,0))/(COUNTIFS($H$3:$H$392,$H27,$U$3:$U$392,">0")-IF(IFERROR($U27,0)>0,1,0)),"") -> 8.1404968 | X27: 6 | Y27: =[1]!wss(AB27,"sec_status","cols=1;rows=1") -> L | AB27: =IF(LEFT(A27,1)="0",MID(A27,2,99),A27) -> 2580.HK | AC27: 16.48 | AD27: 16.1 | AE27: 16.79 | AF27: 15.68 | AG27: 主板 | AI27: 主板 | AJ27: 0
A28: 3288.HK | B28: 海天味业 | C28: 45827 | D28: =IFERROR(IF(ISNUMBER($C28),$C28-2,DATEVALUE($C28)-2),"") -> 45825 | E28: a_plus_h | F28: =IF(AND(G28<>"",G28<>0),1,0) -> 1 | G28: 603288.SH | H28: 必需性消费(HS)-食物饮品(HS)-食品添加剂(HS) | I28: 36.3 | J28: 35 | K28: 36.3 | L28: 10571445720 | M28: 22.93 | N28: 918.15 | O28: =IF(IFERROR(N28*1,0)>=15,1,0) -> 1 | P28: 4.3686 | Q28: 中国国际金融香港证券有限公司,高盛(亚洲)有限责任公司,摩根士丹利亚洲有限公司,中银国际亚洲有限公司,工银国际证券有限公司,交银国际证券有限公司,招银国际融资有限公司,农银国际融资有限公司,农银国际证券有限公司,建银国际金融有限公司,香港上海汇丰银行有限公司,华泰金融控股(香港)有限公司,中信里昂证券有限公司,富途证券国际(香港)有限公司,广发证券(香港)经纪有限公司,中国银河国际证券(香港)有限公司 | R28: =IF(Q28="",0,LEN(Q28)-LEN(SUBSTITUTE(Q28,",",""))+1) -> 16 | U28: 30.94212 | V28: =IFERROR((SUMIFS($U$3:$U$392,$H$3:$H$392,$H28,$U$3:$U$392,">0")-IF(IFERROR($U28,0)>0,$U28,0))/(COUNTIFS($H$3:$H$392,$H28,$U$3:$U$392,">0")-IF(IFERROR($U28,0)>0,1,0)),"") -> 38.802333 | X28: 6 | Y28: =[1]!wss(AB28,"sec_status","cols=1;rows=1") -> L | AB28: =IF(LEFT(A28,1)="0",MID(A28,2,99),A28) -> 3288.HK | AC28: 36.5 | AD28: 37.5 | AE28: 38 | AF28: 36.05 | AG28: 主板 | AH28: H股 | AI28: 主板 | AJ28: 0
A29: 2050.HK | B29: 三花智控 | C29: 45831 | D29: =IFERROR(IF(ISNUMBER($C29),$C29-2,DATEVALUE($C29)-2),"") -> 45829 | E29: a_plus_h | F29: =IF(AND(G29<>"",G29<>0),1,0) -> 1 | G29: 002050.SZ | H29: 工业(HS)-工业工程(HS)-工业零件及器材(HS) | I29: 22.53 | J29: 21.21 | K29: 22.53 | L29: 10736365092 | M29: 23.57 | N29: 747.92 | O29: =IF(IFERROR(N29*1,0)>=15,1,0) -> 1 | P29: 13.9 | Q29: 中国国际金融香港证券有限公司,华泰金融控股(香港)有限公司,农银国际证券有限公司,中银国际亚洲有限公司,财通国际证券有限公司,广发证券(香港)经纪有限公司,浙商国际金融控股有限公司 | R29: =IF(Q29="",0,LEN(Q29)-LEN(SUBSTITUTE(Q29,",",""))+1) -> 7 | U29: 27.916186 | V29: =IFERROR((SUMIFS($U$3:$U$392,$H$3:$H$392,$H29,$U$3:$U$392,">0")-IF(IFERROR($U29,0)>0,$U29,0))/(COUNTIFS($H$3:$H$392,$H29,$U$3:$U$392,">0")-IF(IFERROR($U29,0)>0,1,0)),"") -> 88.140923 | X29: 6 | Y29: =[1]!wss(AB29,"sec_status","cols=1;rows=1") -> L | AB29: =IF(LEFT(A29,1)="0",MID(A29,2,99),A29) -> 2050.HK | AC29: 22.5 | AD29: 20.95 | AE29: 22.55 | AF29: 20.7 | AG29: 主板 | AH29: H股 | AI29: 主板 | AJ29: 0
A30: 1276.HK | B30: 恒瑞医药 | C30: 45800 | D30: =IFERROR(IF(ISNUMBER($C30),$C30-2,DATEVALUE($C30)-2),"") -> 45798 | E30: a_plus_h | F30: =IF(AND(G30<>"",G30<>0),1,0) -> 1 | G30: 600276.SH | H30: 医疗保健业(HS)-药品及生物科技(HS)-药品(HS) | I30: 44.05 | J30: 41.45 | K30: 44.05 | L30: 11373604280 | M30: 17.09 | N30: 454.85 | O30: =IF(IFERROR(N30*1,0)>=15,1,0) -> 1 | P30: 14.715 | Q30: 摩根士丹利亚洲有限公司,花旗环球金融亚洲有限公司,Citigroup Global Markets Limited,华泰金融控股(香港)有限公司,UBS AG Hong Kong Branch,中银国际亚洲有限公司,中信里昂证券有限公司,广发证券(香港)经纪有限公司 | R30: =IF(Q30="",0,LEN(Q30)-LEN(SUBSTITUTE(Q30,",",""))+1) -> 8 | U30: 42.510871 | V30: =IFERROR((SUMIFS($U$3:$U$392,$H$3:$H$392,$H30,$U$3:$U$392,">0")-IF(IFERROR($U30,0)>0,$U30,0))/(COUNTIFS($H$3:$H$392,$H30,$U$3:$U$392,">0")-IF(IFERROR($U30,0)>0,1,0)),"") -> 101.02218 | X30: 6 | Y30: =[1]!wss(AB30,"sec_status","cols=1;rows=1") -> L | AB30: =IF(LEFT(A30,1)="0",MID(A30,2,99),A30) -> 1276.HK | AC30: 55.15 | AD30: 57 | AE30: 60.5 | AF30: 55.15 | AG30: 主板 | AH30: H股 | AI30: 主板 | AJ30: 0
A31: 6623.HK | B31: 陆控 | C31: 45030 | D31: =IFERROR(IF(ISNUMBER($C31),$C31-2,DATEVALUE($C31)-2),"") -> 45028 | E31: main_board_profitable | F31: =IF(AND(G31<>"",G31<>0),1,0) -> 0 | H31: 金融业(HS)-其他金融(HS)-信贷(HS) | L31: 0 | M31: 0 | N31: 0 | O31: =IF(IFERROR(N31*1,0)>=15,1,0) -> 0 | P31: 0 | Q31: 0 | R31: =IF(Q31="",0,LEN(Q31)-LEN(SUBSTITUTE(Q31,",",""))+1) -> 1 | U31: 0 | V31: =IFERROR((SUMIFS($U$3:$U$392,$H$3:$H$392,$H31,$U$3:$U$392,">0")-IF(IFERROR($U31,0)>0,$U31,0))/(COUNTIFS($H$3:$H$392,$H31,$U$3:$U$392,">0")-IF(IFERROR($U31,0)>0,1,0)),"") -> 7.7662206 | Y31: =[1]!wss(AB31,"sec_status","cols=1;rows=1") -> L | AB31: =IF(LEFT(A31,1)="0",MID(A31,2,99),A31) -> 6623.HK | AC31: 34.75 | AD31: 33.5 | AE31: 36.5 | AF31: 33.4 | AG31: 主板 | AI31: 主板 | AJ31: 0
A32: 2245.HK | B32: 力勤资源 | C32: 44896 | D32: =IFERROR(IF(ISNUMBER($C32),$C32-2,DATEVALUE($C32)-2),"") -> 44894 | E32: main_board_profitable | F32: =IF(AND(G32<>"",G32<>0),1,0) -> 0 | H32: 原材料业(HS)-一般金属及矿石(HS)-其他金属及矿物(HS) | I32: 15.8 | J32: 15.6 | K32: 19.96 | L32: 3762969080 | M32: 1.4 | N32: 1.47 | O32: =IF(IFERROR(N32*1,0)>=15,1,0) -> 0 | P32: 0.853 | Q32: 中国国际金融香港证券有限公司,招银国际融资有限公司,中银国际亚洲有限公司,星展亚洲融资有限公司,农银国际证券有限公司,法国巴黎证券(亚洲)有限公司,元库证券有限公司,中国国际金融香港证券有限公司(香港) | R32: =IF(Q32="",0,LEN(Q32)-LEN(SUBSTITUTE(Q32,",",""))+1) -> 8 | U32: 18.214611 | V32: =IFERROR((SUMIFS($U$3:$U$392,$H$3:$H$392,$H32,$U$3:$U$392,">0")-IF(IFERROR($U32,0)>0,$U32,0))/(COUNTIFS($H$3:$H$392,$H32,$U$3:$U$392,">0")-IF(IFERROR($U32,0)>0,1,0)),"") -> 36.882025 | X32: 6 | Y32: =[1]!wss(AB32,"sec_status","cols=1;rows=1") -> L | AB32: =IF(LEFT(A32,1)="0",MID(A32,2,99),A32) -> 2245.HK | AC32: 15.8 | AD32: 15.8 | AE32: 16.02 | AF32: 15.8 | AG32: 主板 | AH32: H股 | AI32: 主板 | AJ32: 0
A33: 0501.HK | B33: 豪威集团 | C33: 46034 | D33: =IFERROR(IF(ISNUMBER($C33),$C33-2,DATEVALUE($C33)-2),"") -> 46032 | E33: a_plus_h | F33: =IF(AND(G33<>"",G33<>0),1,0) -> 1 | G33: 603501.SH | H33: 资讯科技业(HS)-半导体(HS)-半导体Ⅲ(HS) | I33: 104.8 | K33: 104.8 | L33: 5317667280 | M33: 9.73 | N33: 9.28 | O33: =IF(IFERROR(N33*1,0)>=15,1,0) -> 0 | P33: 5.112 | Q33: UBS AG Hong Kong Branch,中国国际金融香港证券有限公司,平安证券(香港)有限公司,广发证券(香港)经纪有限公司,海通国际证券有限公司,中信里昂证券有限公司,淘金者证券(香港)有限公司 | R33: =IF(Q33="",0,LEN(Q33)-LEN(SUBSTITUTE(Q33,",",""))+1) -> 7 | U33: 36.733359 | V33: =IFERROR((SUMIFS($U$3:$U$392,$H$3:$H$392,$H33,$U$3:$U$392,">0")-IF(IFERROR($U33,0)>0,$U33,0))/(COUNTIFS($H$3:$H$392,$H33,$U$3:$U$392,">0")-IF(IFERROR($U33,0)>0,1,0)),"") -> 62.754445 | X33: 6 | Y33: =[1]!wss(AB33,"sec_status","cols=1;rows=1") | AB33: =IF(LEFT(A33,1)="0",MID(A33,2,99),A33) -> 501.HK | AC33: 121.8 | AD33: 108 | AE33: 121.8 | AF33: 108 | AG33: 主板 | AH33: H股 | AI33: 主板 | AJ33: 0
A34: 2097.HK | B34: 蜜雪集团 | C34: 45719 | D34: =IFERROR(IF(ISNUMBER($C34),$C34-2,DATEVALUE($C34)-2),"") -> 45717 | E34: main_board_profitable | F34: =IF(AND(G34<>"",G34<>0),1,0) -> 0 | H34: 必需性消费(HS)-食物饮品(HS)-非酒精饮料(HS) | I34: 202.5 | J34: 202.5 | K34: 202.5 | L34: 3972807000 | M34: 35.23 | N34: 5258.21 | O34: =IF(IFERROR(N34*1,0)>=15,1,0) -> 1 | P34: 5.0776966 | Q34: 招银国际融资有限公司,广发证券(香港)经纪有限公司,工银国际证券有限公司,华泰金融控股(香港)有限公司,中国国际金融香港证券有限公司,UBS AG Hong Kong Branch,高盛(亚洲)有限责任公司,Merrill Lynch (Asia Pacific) Limited | R34: =IF(Q34="",0,LEN(Q34)-LEN(SUBSTITUTE(Q34,",",""))+1) -> 8 | U34: 22.055012 | V34: =IFERROR((SUMIFS($U$3:$U$392,$H$3:$H$392,$H34,$U$3:$U$392,">0")-IF(IFERROR($U34,0)>0,$U34,0))/(COUNTIFS($H$3:$H$392,$H34,$U$3:$U$392,">0")-IF(IFERROR($U34,0)>0,1,0)),"") -> 27.018666 | X34: 6 | Y34: =[1]!wss(AB34,"sec_status","cols=1;rows=1") -> L | AB34: =IF(LEFT(A34,1)="0",MID(A34,2,99),A34) -> 2097.HK | AC34: 290 | AD34: 262 | AE34: 298 | AF34: 256 | AG34: 主板 | AH34: H股 | AI34: 主板 | AJ34: 0
A35: 2585.HK | B35: 梦金园 | C35: 45625 | D35: =IFERROR(IF(ISNUMBER($C35),$C35-2,DATEVALUE($C35)-2),"") -> 45623 | E35: main_board_profitable | F35: =IF(AND(G35<>"",G35<>0),1,0) -> 0 | H35: 非必需性消费(HS)-专业零售(HS)-其他零售商(HS) | I35: 12 | J35: 12 | K35: 14.4 | L35: 527481600 | M35: 0.98 | N35: 20.58 | O35: =IF(IFERROR(N35*1,0)>=15,1,0) -> 1 | P35: 0 | Q35: 农银国际证券有限公司,中国光大证券(香港)有限公司,富途证券国际(香港)有限公司,工银国际证券有限公司,TradeGo Markets Limited,中信里昂证券有限公司 | R35: =IF(Q35="",0,LEN(Q35)-LEN(SUBSTITUTE(Q35,",",""))+1) -> 6 | U35: 12.887822 | V35: =IFERROR((SUMIFS($U$3:$U$392,$H$3:$H$392,$H35,$U$3:$U$392,">0")-IF(IFERROR($U35,0)>0,$U35,0))/(COUNTIFS($H$3:$H$392,$H35,$U$3:$U$392,">0")-IF(IFERROR($U35,0)>0,1,0)),"") -> 13.610448 | X35: 6 | Y35: =[1]!wss(AB35,"sec_status","cols=1;rows=1") -> L | AB35: =IF(LEFT(A35,1)="0",MID(A35,2,99),A35) -> 2585.HK | AC35: 12.9 | AD35: 12.5 | AE35: 13.2 | AF35: 11.2 | AG35: 主板 | AH35: H股 | AI35: 主板 | AJ35: 0
A36: 1828.HK | B36: 富卫集团 | C36: 45845 | D36: =IFERROR(IF(ISNUMBER($C36),$C36-2,DATEVALUE($C36)-2),"") -> 45843 | E36: main_board_profitable | F36: =IF(AND(G36<>"",G36<>0),1,0) -> 0 | H36: 金融业(HS)-保险(HS)-保险Ⅲ(HS) | I36: 38 | J36: 38 | K36: 38 | L36: 3661053000 | M36: 2.32 | N36: 37.13 | O36: =IF(IFERROR(N36*1,0)>=15,1,0) -> 1 | P36: 1.723 | Q36: 摩根士丹利亚洲有限公司,香港上海汇丰银行有限公司,招银国际融资有限公司,高盛(亚洲)有限责任公司,交银国际证券有限公司,建银国际金融有限公司,华泰金融控股(香港)有限公司,工银国际证券有限公司,瑞穗证券亚洲有限公司,日兴证券(香港)有限公司,星展亚洲融资有限公司,华侨银行有限公司,大华继显(香港)有限公司 | R36: =IF(Q36="",0,LEN(Q36)-LEN(SUBSTITUTE(Q36,",",""))+1) -> 13 | U36: 259.24879 | V36: =IFERROR((SUMIFS($U$3:$U$392,$H$3:$H$392,$H36,$U$3:$U$392,">0")-IF(IFERROR($U36,0)>0,$U36,0))/(COUNTIFS($H$3:$H$392,$H36,$U$3:$U$392,">0")-IF(IFERROR($U36,0)>0,1,0)),"") -> 15.752299 | X36: 6 | Y36: =[1]!wss(AB36,"sec_status","cols=1;rows=1") -> L | AB36: =IF(LEFT(A36,1)="0",MID(A36,2,99),A36) -> 1828.HK | AC36: 38.4 | AD36: 38 | AE36: 38.8 | AF36: 37.05 | AG36: 主板 | AI36: 主板 | AJ36: 0
A37: 2865.HK | B37: 钧达股份 | C37: 45785 | D37: =IFERROR(IF(ISNUMBER($C37),$C37-2,DATEVALUE($C37)-2),"") -> 45783 | E37: a_plus_h | F37: =IF(AND(G37<>"",G37<>0),1,0) -> 1 | G37: 002865.SZ | H37: 工业(HS)-工业工程(HS)-新能源物料(HS) | I37: 22.15 | J37: 20.4 | K37: 28.6 | L37: 1405025445 | M37: 1.08 | N37: 3.5 | O37: =IF(IFERROR(N37*1,0)>=15,1,0) -> 0 | P37: 0 | Q37: TradeGo Markets Limited,富强证券有限公司,工银国际证券有限公司,建银国际金融有限公司,中银国际亚洲有限公司,复星国际证券有限公司,富途证券国际(香港)有限公司,广发证券(香港)经纪有限公司,百惠证券有限公司,国证国际证券(香港)有限公司,中国国际金融香港证券有限公司,中信里昂证券有限公司,德意志银行(香港分行),招银国际融资有限公司,华泰金融控股(香港)有限公司,元宇宙(国际)证券有限公司,星河证券有限公司,艾德证券期货有限公司 | R37: =IF(Q37="",0,LEN(Q37)-LEN(SUBSTITUTE(Q37,",",""))+1) -> 18 | U37: -10.152748 | V37: =IFERROR((SUMIFS($U$3:$U$392,$H$3:$H$392,$H37,$U$3:$U$392,">0")-IF(IFERROR($U37,0)>0,$U37,0))/(COUNTIFS($H$3:$H$392,$H37,$U$3:$U$392,">0")-IF(IFERROR($U37,0)>0,1,0)),"") | X37: 6 | Y37: =[1]!wss(AB37,"sec_status","cols=1;rows=1") -> L | AB37: =IF(LEFT(A37,1)="0",MID(A37,2,99),A37) -> 2865.HK | AC37: 26.6 | AD37: 22.2 | AE37: 27.5 | AF37: 22.1 | AG37: 主板 | AH37: H股 | AI37: 主板 | AJ37: 0
A38: 2768.HK | B38: 国恩科技 | C38: 46057 | D38: =IFERROR(IF(ISNUMBER($C38),$C38-2,DATEVALUE($C38)-2),"") -> 46055 | E38: a_plus_h | F38: =IF(AND(G38<>"",G38<>0),1,0) -> 1 | G38: 002768.SZ | H38: 原材料业(HS)-原材料(HS)-特殊化工用品(HS) | I38: 36 | J38: 34 | K38: 42 | L38: 1080000000 | M38: 10.03 | N38: 2251.85 | O38: =IF(IFERROR(N38*1,0)>=15,1,0) -> 1 | P38: 0 | Q38: 招商证券(香港)有限公司,中信里昂证券有限公司,中国国际金融香港证券有限公司,招银国际融资有限公司,老虎证券(香港)环球有限公司,利弗莫尔证券有限公司 | R38: =IF(Q38="",0,LEN(Q38)-LEN(SUBSTITUTE(Q38,",",""))+1) -> 6 | U38: 14.65621 | V38: =IFERROR((SUMIFS($U$3:$U$392,$H$3:$H$392,$H38,$U$3:$U$392,">0")-IF(IFERROR($U38,0)>0,$U38,0))/(COUNTIFS($H$3:$H$392,$H38,$U$3:$U$392,">0")-IF(IFERROR($U38,0)>0,1,0)),"") -> 12.408857 | X38: 6 | Y38: =[1]!wss(AB38,"sec_status","cols=1;rows=1") -> L | AB38: =IF(LEFT(A38,1)="0",MID(A38,2,99),A38) -> 2768.HK | AC38: 40.16 | AD38: 45 | AE38: 50.8 | AF38: 39.8 | AG38: 主板 | AH38: H股 | AI38: 主板 | AJ38: 0
A39: 7618.HK | B39: 京东工业 | C39: 46002 | D39: =IFERROR(IF(ISNUMBER($C39),$C39-2,DATEVALUE($C39)-2),"") -> 46000 | E39: main_board_profitable | F39: =IF(AND(G39<>"",G39<>0),1,0) -> 0 | H39: 工业(HS)-工用支援(HS)-采购及供应链管理(HS) | I39: 14.1 | J39: 12.7 | K39: 15.5 | L39: 3033843420 | M39: 7.88 | N39: 60.52 | O39: =IF(IFERROR(N39*1,0)>=15,1,0) -> 1 | P39: 0.547 | Q39: Merrill Lynch (Asia Pacific) Limited,东方证券(香港)有限公司,工银国际证券有限公司,香港上海汇丰银行有限公司,富途证券国际(香港)有限公司,中银国际亚洲有限公司,农银国际证券有限公司,华泰金融控股(香港)有限公司,海通国际证券有限公司,UBS AG Hong Kong Branch,高盛(亚洲)有限责任公司,民银证券有限公司,中信里昂证券有限公司,摩根士丹利(亚太)有限公司,瑞银集团香港分行,农银国际融资有限公司 | R39: =IF(Q39="",0,LEN(Q39)-LEN(SUBSTITUTE(Q39,",",""))+1) -> 16 | U39: 46.076256 | V39: =IFERROR((SUMIFS($U$3:$U$392,$H$3:$H$392,$H39,$U$3:$U$392,">0")-IF(IFERROR($U39,0)>0,$U39,0))/(COUNTIFS($H$3:$H$392,$H39,$U$3:$U$392,">0")-IF(IFERROR($U39,0)>0,1,0)),"") -> 10.954967 | X39: 6 | Y39: =[1]!wss(AB39,"sec_status","cols=1;rows=1") -> L | AB39: =IF(LEFT(A39,1)="0",MID(A39,2,99),A39) -> 7618.HK | AC39: 14.1 | AD39: 13 | AE39: 14.15 | AF39: 12.66 | AG39: 主板 | AI39: 主板 | AJ39: 0
A40: 9885.HK | B40: 药师帮 | C40: 45105 | D40: =IFERROR(IF(ISNUMBER($C40),$C40-2,DATEVALUE($C40)-2),"") -> 45103 | E40: main_board_profitable | F40: =IF(AND(G40<>"",G40<>0),1,0) -> 0 | H40: 医疗保健业(HS)-药品及生物科技(HS)-药品分销(HS) | I40: 20 | J40: 19 | K40: 23 | L40: 344708000 | M40: 2.08 | N40: 5.6 | O40: =IF(IFERROR(N40*1,0)>=15,1,0) -> 0 | P40: 0.272 | Q40: 中国国际金融香港证券有限公司,招银国际融资有限公司,工银国际证券有限公司,农银国际证券有限公司,复星国际证券有限公司,富途证券国际(香港)有限公司,老虎证券(香港)环球有限公司,华盛资本证券有限公司 | R40: =IF(Q40="",0,LEN(Q40)-LEN(SUBSTITUTE(Q40,",",""))+1) -> 8 | U40: -7.5886866 | V40: =IFERROR((SUMIFS($U$3:$U$392,$H$3:$H$392,$H40,$U$3:$U$392,">0")-IF(IFERROR($U40,0)>0,$U40,0))/(COUNTIFS($H$3:$H$392,$H40,$U$3:$U$392,">0")-IF(IFERROR($U40,0)>0,1,0)),"") | X40: 6 | Y40: =[1]!wss(AB40,"sec_status","cols=1;rows=1") -> L | AB40: =IF(LEFT(A40,1)="0",MID(A40,2,99),A40) -> 9885.HK | AC40: 21.1 | AD40: 23.05 | AE40: 23.3 | AF40: 20.55 | AG40: 主板 | AI40: 主板 | AJ40: 0
...

Sheet 02_ipo_cornerstones
A1: stock_code | B1: ipo_listing_date | C1: cornerstone_raw_name | D1: cornerstone_full_name | E1: ticket_amount_value | F1: ticket_amount_ccy | G1: lockup_months | H1: affiliation_disclosed | I1: unlock_date | J1: controlling_shareholder | K1: notes
A2: Wind代码 ★必填 | B2: (关联) yyyy-mm-dd ★必填 | C2: 招股书原文(不要归一) ★必填 | D2: 全称/带说明 ○选填 | E2: 认购金额数值 ★必填 | F2: 币种 HKD/USD ★必填 | G2: 锁定期 月 ★必填 | H2: 1=确认与发行人关联(名字含发行人 token或员工持股),0=独立财务投资者或未披露 规则法重置 2026-05 | I2: 解禁日 yyyy-mm-dd | J2: 实际控制人 | K2: 备注 ○选填
A3: 03296.HK | B3: 2026-04-23 | C3: JPMAMAPL | D3: JPMAMAPL (J.P. Morgan AM Asia Pac) | E3: 2500000000 | F3: HKD | G3: 6 | J3: prospectus_2026-04-15
A4: 1187.HK | B4: 46148 | C4: ODI TRUST LIMITED | D4: ODI TRUST LIMITED | E4: 7826670 | F4: HKD | G4: 6 | I4: 46332
A5: 1187.HK | B5: 46148 | C5: 蓝思科技(香港)有限公司 | D5: 蓝思科技(香港)有限公司 | E5: 78302097 | F5: HKD | G5: 6 | I5: 46332 | J5: 周群飞
A6: 1187.HK | B6: 46148 | C6: 远信(珠海)私募基金管理有限公司及中国银河国际投资有限公司 | D6: 远信(珠海)私募基金管理有限公司及中国银河国际投资有限公司 | E6: 50971680 | F6: HKD | G6: 6 | I6: 46332 | J6: 刘岩
A7: 1187.HK | B7: 46148 | C7: 盘京港景投资基金 | D7: 盘京港景投资基金 | E7: 39149082 | F7: HKD | J7: XIAO Jian
A8: 1187.HK | B8: 46148 | C8: 大成国际资产管理有限公司 | D8: 大成国际资产管理有限公司 | E8: 15657273 | F8: HKD | G8: 6 | I8: 46332 | J8: 大成基金管理有限公司
A9: 1187.HK | B9: 46148 | C9: 中康科技控股有限公司 | D9: 中康科技控股有限公司 | E9: 15657273 | F9: HKD | G9: 6 | I9: 46332 | J9: 吴郁抒
A10: 1187.HK | B10: 46148 | C10: 黄雪林 | D10: 黄雪林 | E10: 39149082 | F10: HKD | G10: 6 | I10: 46332
A11: 1187.HK | B11: 46148 | C11: 戴钧安 | D11: 戴钧安 | E11: 19574541 | F11: HKD | G11: 6 | I11: 46332
A12: 1187.HK | B12: 46148 | C12: 陆勤超 | D12: 陆勤超 | E12: 15657273 | F12: HKD | G12: 6 | I12: 46332
A13: 1187.HK | B13: 46148 | C13: 长沙雨丰科技有限公司 | D13: 长沙雨丰科技有限公司 | E13: 54696231 | F13: HKD | G13: 6 | I13: 46332 | J13: 湖南环保科技产业园管理委员会
A14: 1187.HK | B14: 46148 | C14: 香港汉清达实业有限公司 | D14: 香港汉清达实业有限公司 | E14: 19574541 | F14: HKD | G14: 6 | I14: 46332 | J14: 侯守山
A15: 1187.HK | B15: 46148 | C15: FR M CONSULTING CO., LTD | D15: FR M CONSULTING CO., LTD | E15: 23487876 | F15: HKD | G15: 6 | I15: 46332 | J15: 张国锋
A16: 1609.HK | B16: 46147 | C16: 大湾区发展基金管理有限公司 | D16: 大湾区发展基金管理有限公司 | E16: 54834950 | F16: HKD | G16: 6 | I16: 46331
A17: 1609.HK | B17: 46147 | C17: JSC International Investment Fund SPC | D17: JSC International Investment Fund SPC | E17: 193902175 | F17: HKD | G17: 6 | I17: 46331
A18: 1609.HK | B18: 46147 | C18: OAP IV (HK) Limited | D18: OAP IV (HK) Limited | E18: 39168525 | F18: HKD | G18: 6 | I18: 46331
A19: 6810.HK | B19: 46141 | C19: China Orient International Asset Management Limited - China Orient Enhanced Income Fund | D19: China Orient International Asset Management Limited - China Orient Enhanced Income Fund | E19: 39156986 | F19: HKD | G19: 6 | I19: 46324 | J19: 中央汇金投资有限责任公司
A20: 6810.HK | B20: 46141 | C20: XINWUTANG CO., LIMITED | D20: XINWUTANG CO., LIMITED | E20: 247250102 | F20: HKD | G20: 6 | I20: 46324 | J20: 嘉善县财政局
A21: 1879.HK | B21: 46140 | C21: 上海中移数字转型产业私募基金合伙企业(有限合伙) | D21: 上海中移数字转型产业私募基金合伙企业(有限合伙) | E21: 114360768 | F21: HKD | G21: 6 | I21: 46323
A22: 1879.HK | B22: 46140 | C22: Alibaba Investment Limited | D22: Alibaba Investment Limited | E22: 203659776 | F22: HKD | G22: 6 | I22: 46323 | J22: 阿里巴巴集团控股有限公司
A23: 1879.HK | B23: 46140 | C23: 富达基金(香港)有限公司 | D23: 富达基金(香港)有限公司 | E23: 117496236 | F23: HKD | G23: 6 | I23: 46323
A24: 1879.HK | B24: 46140 | C24: GIC PRIVATE LIMITED | D24: GIC PRIVATE LIMITED | E24: 156660732 | F24: HKD | G24: 6 | I24: 46323
A25: 1879.HK | B25: 46140 | C25: BlackRock, Inc. | D25: BlackRock, Inc. | E25: 117496236 | F25: HKD | G25: 6 | I25: 46323
A26: 1879.HK | B26: 46140 | C26: Baillie Gifford Overseas Limited及Baillie Gifford & Co | D26: Baillie Gifford Overseas Limited及Baillie Gifford & Co | E26: 117496236 | F26: HKD | G26: 6 | I26: 46323
A27: 1879.HK | B27: 46140 | C27: 工银理财有限责任公司 | D27: 工银理财有限责任公司 | E27: 19582248 | F27: HKD | G27: 6 | I27: 46323 | J27: 中国工商银行股份有限公司
A28: 1879.HK | B28: 46140 | C28: 中国平安资产管理(香港)有限公司 | D28: 中国平安资产管理(香港)有限公司 | E28: 19582248 | F28: HKD | G28: 6 | I28: 46323 | J28: 中国平安保险(集团)股份有限公司
A29: 1879.HK | B29: 46140 | C29: 中兴通讯(香港)有限公司 | D29: 中兴通讯(香港)有限公司 | E29: 33682236 | F29: HKD | G29: 6 | I29: 46323 | J29: 中兴通讯股份有限公司
A30: 1879.HK | B30: 46140 | C30: 3W Fund Management Limited | D30: 3W Fund Management Limited | E30: 78328992 | F30: HKD | G30: 6 | I30: 46323
A31: 1879.HK | B31: 46140 | C31: TEMASEK HOLDINGS (PRIVATE) LIMITED | D31: TEMASEK HOLDINGS (PRIVATE) LIMITED | E31: 117496236 | F31: HKD | G31: 6 | I31: 46323
A32: 1879.HK | B32: 46140 | C32: Aspex Master Fund | D32: Aspex Master Fund | E32: 78328992 | F32: HKD | G32: 6 | I32: 46323
A33: 1879.HK | B33: 46140 | C33: CPE Fir Investment Limited | D33: CPE Fir Investment Limited | E33: 39164496 | F33: HKD | G33: 6 | I33: 46323
A34: 1879.HK | B34: 46140 | C34: HHLR ADVISORS, LTD. | D34: HHLR ADVISORS, LTD. | E34: 78328992 | F34: HKD | G34: 6 | I34: 46323
A35: 1879.HK | B35: 46140 | C35: Schroder Investment Management (Singapore) Ltd,Schroder Investment Management (Hong Kong) Limited及Schroder Investment Management Limited | D35: Schroder Investment Management (Singapore) Ltd,Schroder Investment Management (Hong Kong) Limited及Schroder Investment Management Limited | E35: 117496236 | F35: HKD | G35: 6 | I35: 46323
A36: 1879.HK | B36: 46140 | C36: 未来资产证券(香港)有限公司 | D36: 未来资产证券(香港)有限公司 | E36: 39164496 | F36: HKD | G36: 6 | I36: 46323 | J36: MIRAE ASSET CAPITAL CO., LTD.
A37: 1879.HK | B37: 46140 | C37: 联想集团有限公司 | D37: 联想集团有限公司 | E37: 39164496 | F37: HKD | G37: 6 | I37: 46323
A38: 1879.HK | B38: 46140 | C38: 广发基金管理有限公司及广发国际资产管理有限公司 | D38: 广发基金管理有限公司及广发国际资产管理有限公司 | E38: 39161748 | F38: HKD | G38: 6 | I38: 46323
A39: 1879.HK | B39: 46140 | C39: 景林资产管理香港有限公司,上海景林资产管理有限公司及CICC Financial Trading Limited | D39: 景林资产管理香港有限公司,上海景林资产管理有限公司及CICC Financial Trading Limited | E39: 39161748 | F39: HKD | G39: 6 | I39: 46323
A40: 1879.HK | B40: 46140 | C40: 瑞银环球资产管理(新加坡)有限公司 | D40: 瑞银环球资产管理(新加坡)有限公司 | E40: 78328992 | F40: HKD | G40: 6 | I40: 46323 | J40: UBS Asset Management AG
...

Sheet 03_company_fundamentals
A1: stock_code | B1: ipo_year | C1: revenue_n3 | D1: revenue_n2 | E1: revenue_n1 | F1: net_profit_n3 | G1: net_profit_n2 | H1: net_profit_n1 | I1: gross_margin_n3 | J1: gross_margin_n2 | K1: gross_margin_n1 | L1: roe_avg_3y | M1: net_debt_to_ebitda | N1: fcf_positive_years_3y | O1: top1_customer_pct_n1 | P1: _diag_revenue_2023 | Q1: _diag_revenue_2024 | R1: _diag_revenue_2025 | S1: _diag_netprofit_2023 | T1: _diag_netprofit_2024 | U1: _diag_netprofit_2025 | V1: _diag_grossmargin_2023 | W1: _diag_grossmargin_2024 | X1: grossmargin_2025
A2: Wind代码 ★必填 | B2: 上市年份(N年) 从01_ipo_master.listing_date提取 ★自动 | C2: N-3年营收 (rptDate=ipo_year-3) RMB亿 ★必填 | D2: N-2年营收 (rptDate=ipo_year-2) RMB亿 ★必填 | E2: N-1年营收 (rptDate=ipo_year-1) RMB亿 ★必填 | F2: N-3年净利润 (rptDate=ipo_year-3) RMB亿 ★必填 | G2: N-2年净利润 (rptDate=ipo_year-2) RMB亿 ★必填 | H2: N-1年净利润 (rptDate=ipo_year-1) RMB亿 ★必填 | I2: N-3年毛利率 (rptDate=ipo_year-3) % ★必填 | J2: N-2年毛利率 (rptDate=ipo_year-2) % ★必填 | K2: N-1年毛利率 (rptDate=ipo_year-1) % ★必填 | L2: N-1年ROE (rptDate=ipo_year-1) % ○选填 | M2: N-1年资产负债率 (rptDate=ipo_year-1) % ○选填 | N2: 近3年自由现金流为正的年数 0-3 ○选填 | O2: N-1 年第一大客户收入占比 % ○选填 | P2: raw 2023 (备份) | Q2: raw 2024 (备份) | R2: raw 2025 (备份) | S2: raw 2023 (备份) | T2: raw 2024 (备份) | U2: raw 2025 (备份) | V2: raw 2023 (备份) | W2: raw 2024 (备份) | X2: raw 2025 (备份)
A3: 3296.HK | B3: =IFERROR(YEAR(VLOOKUP($A3,'01_ipo_master'!$A:$C,3,FALSE)),YEAR(VLOOKUP("0"&$A3,'01_ipo_master'!$A:$C,3,FALSE))) -> 2026 | C3: =[1]!wss($A3:$A3,"hks_stm_is","item=83","rptDate="&($B3-3)&"1231","rptType=1","currencyType=Cur=CNY","WssConvert=0","WssDivide=8","showcodes=N","cols=1;rows=1") -> 853.38484 | D3: =[1]!wss($A3:$A3,"hks_stm_is","item=83","rptDate="&($B3-2)&"1231","rptType=1","currencyType=Cur=CNY","WssConvert=0","WssDivide=8","showcodes=N","cols=1;rows=1") -> 1098.7799 | E3: =[1]!wss($A3:$A3,"hks_stm_is","item=83","rptDate="&($B3-1)&"1231","rptType=1","currencyType=Cur=CNY","WssConvert=0","WssDivide=8","showcodes=N","cols=1;rows=1") -> 1714.3693 | F3: =[1]!wss($A3:$A3,"hks_stm_is","item=61","rptDate="&($B3-3)&"1231","rptType=1","currencyType=Cur=CNY","WssConvert=0","WssDivide=8","showcodes=N","cols=1;rows=1") -> 27.08451 | G3: =[1]!wss($A3:$A3,"hks_stm_is","item=61","rptDate="&($B3-2)&"1231","rptType=1","currencyType=Cur=CNY","WssConvert=0","WssDivide=8","showcodes=N","cols=1;rows=1") -> 29.2894 | H3: =[1]!wss($A3:$A3,"hks_stm_is","item=61","rptDate="&($B3-1)&"1231","rptType=1","currencyType=Cur=CNY","WssConvert=0","WssDivide=8","showcodes=N","cols=1;rows=1") -> 40.81338 | I3: =[1]!wss($A3:$A3,"hks_fa_grossprofitmargin","rptDate="&($B3-3)&"1231","WssConvert=0","showcodes=N","cols=1;rows=1") -> 10.941 | J3: =[1]!wss($A3:$A3,"hks_fa_grossprofitmargin","rptDate="&($B3-2)&"1231","WssConvert=0","showcodes=N","cols=1;rows=1") -> 8.995 | K3: =[1]!wss($A3:$A3,"hks_fa_grossprofitmargin","rptDate="&($B3-1)&"1231","WssConvert=0","showcodes=N","cols=1;rows=1") -> 7.7174 | L3: =[1]!wss($A3:$A3,"hks_fa_roe","rptDate="&($B3-1)&"1231","WssConvert=0","showcodes=N","cols=1;rows=1") -> 16.8858 | M3: =[1]!wss($A3:$A3,"hks_fa_debttoassets","rptDate="&($B3-1)&"1231","WssConvert=0","showcodes=N","cols=1;rows=1") -> 72.6156 | N3: 取数代码 | O3: 诊断H3:净利字段ID占位为W45364519,如报错请在Wind"指标查询"搜"归母净利润"拿准确ID | P3: 853.38484 | Q3: 1098.7799 | R3: 1714.3693 | S3: 27.08451 | T3: 29.2894 | U3: 40.81338 | V3: 10.941 | W3: 8.995 | X3: 7.7174
A4: 2555.HK | B4: =IFERROR(YEAR(VLOOKUP($A4,'01_ipo_master'!$A:$C,3,FALSE)),YEAR(VLOOKUP("0"&$A4,'01_ipo_master'!$A:$C,3,FALSE))) -> 2024 | C4: =[1]!wss($A4:$A4,"hks_stm_is","item=83","rptDate="&($B4-3)&"1231","rptType=1","currencyType=Cur=CNY","WssConvert=0","WssDivide=8","showcodes=N","cols=1;rows=1") -> 36.44209 | D4: =[1]!wss($A4:$A4,"hks_stm_is","item=83","rptDate="&($B4-2)&"1231","rptType=1","currencyType=Cur=CNY","WssConvert=0","WssDivide=8","showcodes=N","cols=1;rows=1") -> 42.3167 | E4: =[1]!wss($A4:$A4,"hks_stm_is","item=83","rptDate="&($B4-1)&"1231","rptType=1","currencyType=Cur=CNY","WssConvert=0","WssDivide=8","showcodes=N","cols=1;rows=1") -> 57.04307 | F4: =[1]!wss($A4:$A4,"hks_stm_is","item=61","rptDate="&($B4-3)&"1231","rptType=1","currencyType=Cur=CNY","WssConvert=0","WssDivide=8","showcodes=N","cols=1;rows=1") -> 7.55816 | G4: =[1]!wss($A4:$A4,"hks_stm_is","item=61","rptDate="&($B4-2)&"1231","rptType=1","currencyType=Cur=CNY","WssConvert=0","WssDivide=8","showcodes=N","cols=1;rows=1") -> 9.54316 | H4: =[1]!wss($A4:$A4,"hks_stm_is","item=61","rptDate="&($B4-1)&"1231","rptType=1","currencyType=Cur=CNY","WssConvert=0","WssDivide=8","showcodes=N","cols=1;rows=1") -> 11.39211 | I4: =[1]!wss($A4:$A4,"hks_fa_grossprofitmargin","rptDate="&($B4-3)&"1231","WssConvert=0","showcodes=N","cols=1;rows=1") -> 35.7016 | J4: =[1]!wss($A4:$A4,"hks_fa_grossprofitmargin","rptDate="&($B4-2)&"1231","WssConvert=0","showcodes=N","cols=1;rows=1") -> 34.4117 | K4: =[1]!wss($A4:$A4,"hks_fa_grossprofitmargin","rptDate="&($B4-1)&"1231","WssConvert=0","showcodes=N","cols=1;rows=1") -> 34.4263 | L4: =[1]!wss($A4:$A4,"hks_fa_roe","rptDate="&($B4-1)&"1231","WssConvert=0","showcodes=N","cols=1;rows=1") -> 154.6065 | M4: =[1]!wss($A4:$A4,"hks_fa_debttoassets","rptDate="&($B4-1)&"1231","WssConvert=0","showcodes=N","cols=1;rows=1") -> 72.5605 | N4: =IFERROR(IF(VLOOKUP($A4,'01_ipo_master'!$A:$G,7,0)="",$A4,VLOOKUP($A4,'01_ipo_master'!$A:$G,7,0)),$A4) -> 2555.HK | P4: 57.04307 | Q4: 49.17997 | R4: 53.95068 | S4: 11.39211 | T4: 4.72184 | U4: 8.04897 | V4: 34.4263 | W4: 31.2054 | X4: 32.5082
A5: 3750.HK | B5: =IFERROR(YEAR(VLOOKUP($A5,'01_ipo_master'!$A:$C,3,FALSE)),YEAR(VLOOKUP("0"&$A5,'01_ipo_master'!$A:$C,3,FALSE))) -> 2025 | C5: =[1]!wss($A5:$A5,"hks_stm_is","item=83","rptDate="&($B5-3)&"1231","rptType=1","currencyType=Cur=CNY","WssConvert=0","WssDivide=8","showcodes=N","cols=1;rows=1") -> 3285.9399 | D5: =[1]!wss($A5:$A5,"hks_stm_is","item=83","rptDate="&($B5-2)&"1231","rptType=1","currencyType=Cur=CNY","WssConvert=0","WssDivide=8","showcodes=N","cols=1;rows=1") -> 4009.1705 | E5: =[1]!wss($A5:$A5,"hks_stm_is","item=83","rptDate="&($B5-1)&"1231","rptType=1","currencyType=Cur=CNY","WssConvert=0","WssDivide=8","showcodes=N","cols=1;rows=1") -> 3620.1255 | F5: =[1]!wss($A5:$A5,"hks_stm_is","item=61","rptDate="&($B5-3)&"1231","rptType=1","currencyType=Cur=CNY","WssConvert=0","WssDivide=8","showcodes=N","cols=1;rows=1") -> 307.29164 | G5: =[1]!wss($A5:$A5,"hks_stm_is","item=61","rptDate="&($B5-2)&"1231","rptType=1","currencyType=Cur=CNY","WssConvert=0","WssDivide=8","showcodes=N","cols=1;rows=1") -> 447.02249 | H5: =[1]!wss($A5:$A5,"hks_stm_is","item=61","rptDate="&($B5-1)&"1231","rptType=1","currencyType=Cur=CNY","WssConvert=0","WssDivide=8","showcodes=N","cols=1;rows=1") -> 520.32846 | I5: =[1]!wss($A5:$A5,"hks_fa_grossprofitmargin","rptDate="&($B5-3)&"1231","WssConvert=0","showcodes=N","cols=1;rows=1") -> 15.1739 | J5: =[1]!wss($A5:$A5,"hks_fa_grossprofitmargin","rptDate="&($B5-2)&"1231","WssConvert=0","showcodes=N","cols=1;rows=1") -> 16.5641 | K5: =[1]!wss($A5:$A5,"hks_fa_grossprofitmargin","rptDate="&($B5-1)&"1231","WssConvert=0","showcodes=N","cols=1;rows=1") -> 21.1433 | L5: =[1]!wss($A5:$A5,"hks_fa_roe","rptDate="&($B5-1)&"1231","WssConvert=0","showcodes=N","cols=1;rows=1") -> 23.4046 | M5: =[1]!wss($A5:$A5,"hks_fa_debttoassets","rptDate="&($B5-1)&"1231","WssConvert=0","showcodes=N","cols=1;rows=1") -> 65.2382 | P5: 4009.1705 | Q5: 3620.1255 | R5: 4237.0183 | S5: 447.02249 | T5: 520.32846 | U5: 722.01282 | V5: 16.5641 | W5: 21.1433 | X5: 26.2728
A6: 0300.HK | B6: =IFERROR(YEAR(VLOOKUP($A6,'01_ipo_master'!$A:$C,3,FALSE)),YEAR(VLOOKUP("0"&$A6,'01_ipo_master'!$A:$C,3,FALSE))) -> 2024 | C6: =[1]!wss($A6:$A6,"hks_stm_is","item=83","rptDate="&($B6-3)&"1231","rptType=1","currencyType=Cur=CNY","WssConvert=0","WssDivide=8","showcodes=N","cols=1;rows=1") -> 3433.6083 | D6: =[1]!wss($A6:$A6,"hks_stm_is","item=83","rptDate="&($B6-2)&"1231","rptType=1","currencyType=Cur=CNY","WssConvert=0","WssDivide=8","showcodes=N","cols=1;rows=1") -> 3457.0871 | E6: =[1]!wss($A6:$A6,"hks_stm_is","item=83","rptDate="&($B6-1)&"1231","rptType=1","currencyType=Cur=CNY","WssConvert=0","WssDivide=8","showcodes=N","cols=1;rows=1") -> 3737.098 | F6: =[1]!wss($A6:$A6,"hks_stm_is","item=61","rptDate="&($B6-3)&"1231","rptType=1","currencyType=Cur=CNY","WssConvert=0","WssDivide=8","showcodes=N","cols=1;rows=1") -> 285.8698 | G6: =[1]!wss($A6:$A6,"hks_stm_is","item=61","rptDate="&($B6-2)&"1231","rptType=1","currencyType=Cur=CNY","WssConvert=0","WssDivide=8","showcodes=N","cols=1;rows=1") -> 295.53342 | H6: =[1]!wss($A6:$A6,"hks_stm_is","item=61","rptDate="&($B6-1)&"1231","rptType=1","currencyType=Cur=CNY","WssConvert=0","WssDivide=8","showcodes=N","cols=1;rows=1") -> 337.21536 | I6: =[1]!wss($A6:$A6,"hks_fa_grossprofitmargin","rptDate="&($B6-3)&"1231","WssConvert=0","showcodes=N","cols=1;rows=1") -> 22.3992 | J6: =[1]!wss($A6:$A6,"hks_fa_grossprofitmargin","rptDate="&($B6-2)&"1231","WssConvert=0","showcodes=N","cols=1;rows=1") -> 24.1206 | K6: =[1]!wss($A6:$A6,"hks_fa_grossprofitmargin","rptDate="&($B6-1)&"1231","WssConvert=0","showcodes=N","cols=1;rows=1") -> 26.3278 | L6: =[1]!wss($A6:$A6,"hks_fa_roe","rptDate="&($B6-1)&"1231","WssConvert=0","showcodes=N","cols=1;rows=1") -> 22.054 | M6: =[1]!wss($A6:$A6,"hks_fa_debttoassets","rptDate="&($B6-1)&"1231","WssConvert=0","showcodes=N","cols=1;rows=1") -> 64.1389 | P6: 3737.098 | Q6: 4090.8427 | R6: 4585.0241 | S6: 337.21536 | T6: 385.38987 | U6: 439.45411 | V6: 26.3278 | W6: 26.1808 | X6: 26.1809
A7: 6936.HK | B7: =IFERROR(YEAR(VLOOKUP($A7,'01_ipo_master'!$A:$C,3,FALSE)),YEAR(VLOOKUP("0"&$A7,'01_ipo_master'!$A:$C,3,FALSE))) -> 2024 | C7: =[1]!wss($A7:$A7,"hks_stm_is","item=83","rptDate="&($B7-3)&"1231","rptType=1","currencyType=Cur=CNY","WssConvert=0","WssDivide=8","showcodes=N","cols=1;rows=1") -> 2071.8665 | D7: =[1]!wss($A7:$A7,"hks_stm_is","item=83","rptDate="&($B7-2)&"1231","rptType=1","currencyType=Cur=CNY","WssConvert=0","WssDivide=8","showcodes=N","cols=1;rows=1") -> 2674.9041 | E7: =[1]!wss($A7:$A7,"hks_stm_is","item=83","rptDate="&($B7-1)&"1231","rptType=1","currencyType=Cur=CNY","WssConvert=0","WssDivide=8","showcodes=N","cols=1;rows=1") -> 2584.094 | F7: =[1]!wss($A7:$A7,"hks_stm_is","item=61","rptDate="&($B7-3)&"1231","rptType=1","currencyType=Cur=CNY","WssConvert=0","WssDivide=8","showcodes=N","cols=1;rows=1") -> 47.31979 | G7: =[1]!wss($A7:$A7,"hks_stm_is","item=61","rptDate="&($B7-2)&"1231","rptType=1","currencyType=Cur=CNY","WssConvert=0","WssDivide=8","showcodes=N","cols=1;rows=1") -> 62.27058 | H7: =[1]!wss($A7:$A7,"hks_stm_is","item=61","rptDate="&($B7-1)&"1231","rptType=1","currencyType=Cur=CNY","WssConvert=0","WssDivide=8","showcodes=N","cols=1;rows=1") -> 82.34493 | I7: =[1]!wss($A7:$A7,"hks_fa_grossprofitmargin","rptDate="&($B7-3)&"1231","WssConvert=0","showcodes=N","cols=1;rows=1") -> 12.4417 | J7: =[1]!wss($A7:$A7,"hks_fa_grossprofitmargin","rptDate="&($B7-2)&"1231","WssConvert=0","showcodes=N","cols=1;rows=1") -> 12.3415 | K7: =[1]!wss($A7:$A7,"hks_fa_grossprofitmargin","rptDate="&($B7-1)&"1231","WssConvert=0","showcodes=N","cols=1;rows=1") -> 12.6287 | L7: =[1]!wss($A7:$A7,"hks_fa_roe","rptDate="&($B7-1)&"1231","WssConvert=0","showcodes=N","cols=1;rows=1") -> 9.1978 | M7: =[1]!wss($A7:$A7,"hks_fa_debttoassets","rptDate="&($B7-1)&"1231","WssConvert=0","showcodes=N","cols=1;rows=1") -> 53.3688 | P7: 2584.094 | Q7: 2844.2006 | R7: 3082.2665 | S7: 82.34493 | T7: 101.70427 | U7: 111.17216 | V7: 12.6287 | W7: 13.6755 | X7: 13.0695
A8: 9973.HK | B8: =IFERROR(YEAR(VLOOKUP($A8,'01_ipo_master'!$A:$C,3,FALSE)),YEAR(VLOOKUP("0"&$A8,'01_ipo_master'!$A:$C,3,FALSE))) -> 2025 | C8: =[1]!wss($A8:$A8,"hks_stm_is","item=83","rptDate="&($B8-3)&"1231","rptType=1","currencyType=Cur=CNY","WssConvert=0","WssDivide=8","showcodes=N","cols=1;rows=1") -> 926.18 | D8: =[1]!wss($A8:$A8,"hks_stm_is","item=83","rptDate="&($B8-2)&"1231","rptType=1","currencyType=Cur=CNY","WssConvert=0","WssDivide=8","showcodes=N","cols=1;rows=1") -> 1632.05 | E8: =[1]!wss($A8:$A8,"hks_stm_is","item=83","rptDate="&($B8-1)&"1231","rptType=1","currencyType=Cur=CNY","WssConvert=0","WssDivide=8","showcodes=N","cols=1;rows=1") -> 2698.97 | F8: =[1]!wss($A8:$A8,"hks_stm_is","item=61","rptDate="&($B8-3)&"1231","rptType=1","currencyType=Cur=CNY","WssConvert=0","WssDivide=8","showcodes=N","cols=1;rows=1") -> 62.66 | G8: =[1]!wss($A8:$A8,"hks_stm_is","item=61","rptDate="&($B8-2)&"1231","rptType=1","currencyType=Cur=CNY","WssConvert=0","WssDivide=8","showcodes=N","cols=1;rows=1") -> 119.53 | H8: =[1]!wss($A8:$A8,"hks_stm_is","item=61","rptDate="&($B8-1)&"1231","rptType=1","currencyType=Cur=CNY","WssConvert=0","WssDivide=8","showcodes=N","cols=1;rows=1") -> 141.35 | I8: =[1]!wss($A8:$A8,"hks_fa_grossprofitmargin","rptDate="&($B8-3)&"1231","WssConvert=0","showcodes=N","cols=1;rows=1") -> 13.8256 | J8: =[1]!wss($A8:$A8,"hks_fa_grossprofitmargin","rptDate="&($B8-2)&"1231","WssConvert=0","showcodes=N","cols=1;rows=1") -> 15.986 | K8: =[1]!wss($A8:$A8,"hks_fa_grossprofitmargin","rptDate="&($B8-1)&"1231","WssConvert=0","showcodes=N","cols=1;rows=1") -> 13.4525 | L8: =[1]!wss($A8:$A8,"hks_fa_roe","rptDate="&($B8-1)&"1231","WssConvert=0","showcodes=N","cols=1;rows=1") -> 67.4074 | M8: =[1]!wss($A8:$A8,"hks_fa_debttoassets","rptDate="&($B8-1)&"1231","WssConvert=0","showcodes=N","cols=1;rows=1") -> 87.8858 | P8: 1632.05 | Q8: 2698.97 | R8: 3002.87 | S8: 119.53 | T8: 141.35 | U8: 190.19 | V8: 15.986 | W8: 13.4525 | X8: 13.8011
A9: 2714.HK | B9: =IFERROR(YEAR(VLOOKUP($A9,'01_ipo_master'!$A:$C,3,FALSE)),YEAR(VLOOKUP("0"&$A9,'01_ipo_master'!$A:$C,3,FALSE))) -> 2026 | C9: =[1]!wss($A9:$A9,"hks_stm_is","item=83","rptDate="&($B9-3)&"1231","rptType=1","currencyType=Cur=CNY","WssConvert=0","WssDivide=8","showcodes=N","cols=1;rows=1") -> 1108.6073 | D9: =[1]!wss($A9:$A9,"hks_stm_is","item=83","rptDate="&($B9-2)&"1231","rptType=1","currencyType=Cur=CNY","WssConvert=0","WssDivide=8","showcodes=N","cols=1;rows=1") -> 1379.4689 | E9: =[1]!wss($A9:$A9,"hks_stm_is","item=83","rptDate="&($B9-1)&"1231","rptType=1","currencyType=Cur=CNY","WssConvert=0","WssDivide=8","showcodes=N","cols=1;rows=1") -> 1441.4497 | F9: =[1]!wss($A9:$A9,"hks_stm_is","item=61","rptDate="&($B9-3)&"1231","rptType=1","currencyType=Cur=CNY","WssConvert=0","WssDivide=8","showcodes=N","cols=1;rows=1") -> -42.632808 | G9: =[1]!wss($A9:$A9,"hks_stm_is","item=61","rptDate="&($B9-2)&"1231","rptType=1","currencyType=Cur=CNY","WssConvert=0","WssDivide=8","showcodes=N","cols=1;rows=1") -> 178.8126 | H9: =[1]!wss($A9:$A9,"hks_stm_is","item=61","rptDate="&($B9-1)&"1231","rptType=1","currencyType=Cur=CNY","WssConvert=0","WssDivide=8","showcodes=N","cols=1;rows=1") -> 154.86891 | I9: =[1]!wss($A9:$A9,"hks_fa_grossprofitmargin","rptDate="&($B9-3)&"1231","WssConvert=0","showcodes=N","cols=1;rows=1") -> 3.1084 | J9: =[1]!wss($A9:$A9,"hks_fa_grossprofitmargin","rptDate="&($B9-2)&"1231","WssConvert=0","showcodes=N","cols=1;rows=1") -> 19.0511 | K9: =[1]!wss($A9:$A9,"hks_fa_grossprofitmargin","rptDate="&($B9-1)&"1231","WssConvert=0","showcodes=N","cols=1;rows=1") -> 17.8181 | L9: =[1]!wss($A9:$A9,"hks_fa_roe","rptDate="&($B9-1)&"1231","WssConvert=0","showcodes=N","cols=1;rows=1") -> 20.6877 | M9: =[1]!wss($A9:$A9,"hks_fa_debttoassets","rptDate="&($B9-1)&"1231","WssConvert=0","showcodes=N","cols=1;rows=1") -> 54.1508 | P9: 1108.6073 | Q9: 1379.4689 | R9: 1441.4497 | S9: -42.632808 | T9: 178.8126 | U9: 154.86891 | V9: 3.1084 | W9: 19.0511 | X9: 17.8181
